<sdf version='1.5'>
  <world name='default'>
    <light name='sun' type='directional'>
      <cast_shadows>1</cast_shadows>
      <pose>0 0 10 0 -0 0</pose>
      <diffuse>0.8 0.8 0.8 1</diffuse>
      <specular>0.1 0.1 0.1 1</specular>
      <attenuation>
        <range>1000</range>
        <constant>0.9</constant>
        <linear>0.01</linear>
        <quadratic>0.001</quadratic>
      </attenuation>
      <direction>-0.5 0.5 -1</direction>
    </light>
    <model name='ground_plane'>
      <static>1</static>
      <link name='link'>
        <collision name='collision'>
          <geometry>
            <plane>
              <normal>0 0 1</normal>
              <size>100 100</size>
            </plane>
          </geometry>
          <surface>
            <friction>
              <ode>
                <mu>100</mu>
                <mu2>50</mu2>
              </ode>
              <torsional>
                <ode/>
              </torsional>
            </friction>
            <contact>
              <ode/>
            </contact>
            <bounce/>
          </surface>
          <max_contacts>10</max_contacts>
        </collision>
        <visual name='visual'>
          <cast_shadows>0</cast_shadows>
          <geometry>
            <plane>
              <normal>0 0 1</normal>
              <size>100 100</size>
            </plane>
          </geometry>
          <material>
            <script>
              <uri>file://media/materials/scripts/gazebo.material</uri>
              <name>Gazebo/Grey</name>
            </script>
          </material>
        </visual>
        <self_collide>0</self_collide>
        <kinematic>0</kinematic>
        <gravity>1</gravity>
        <enable_wind>0</enable_wind>
      </link>
    </model>
    <atmosphere type='adiabatic'/>
    <physics name='default_physics' default='0' type='ode'>
      <max_step_size>0.001</max_step_size>
      <real_time_factor>1</real_time_factor>
      <real_time_update_rate>1000</real_time_update_rate>
      <gravity>0 0 -9.8</gravity>
      <magnetic_field>6e-06 2.3e-05 -4.2e-05</magnetic_field>
    </physics>
    <scene>
      <ambient>0.4 0.4 0.4 1</ambient>
      <background>0.7 0.7 0.7 1</background>
      <shadows>1</shadows>
    </scene>
    <spherical_coordinates>
      <surface_model>EARTH_WGS84</surface_model>
      <latitude_deg>0</latitude_deg>
      <longitude_deg>0</longitude_deg>
      <elevation>0</elevation>
      <heading_deg>0</heading_deg>
    </spherical_coordinates>
    <state world_name='default'>
      <sim_time>862 337000000</sim_time>
      <real_time>256 173029566</real_time>
      <wall_time>1548172571 456036546</wall_time>
      <iterations>0</iterations>
      <model name='Big_box'>
        <pose>1.16572 2.08535 0.536483 -0.016876 -5.9e-05 -0.005738</pose>
        <link name='link'>
          <pose>1.69129 1.96426 0.149463 -1.57078 -5.9e-05 -0.005738</pose>
          <velocity>0 0 0 0 -0 0</velocity>
          <acceleration>0 0 0 0 -0 0</acceleration>
          <wrench>0 0 0 0 -0 0</wrench>
        </link>
      </model>
      <model name='Construction Barrel_0'>
        <pose>9.26683 -7.70095 0.049999 3e-06 0 0.000137</pose>
        <link name='link'>
          <pose>9.26683 -7.70095 0.049999 3e-06 0 0.000137</pose>
          <velocity>0 0 0 0 -0 0</velocity>
          <acceleration>1.88405 -3.55482 -0.738491 -0.536076 -1.55964 -3.13135</acceleration>
          <wrench>942.024 -1777.41 -369.245 0 -0 0</wrench>
        </link>
      </model>
      <model name='Construction Barrel_1'>
        <pose>9.4909 7.33823 0.049999 4e-06 0 0.00014</pose>
        <link name='link'>
          <pose>9.4909 7.33823 0.049999 4e-06 0 0.00014</pose>
          <velocity>0 0 0 0 -0 0</velocity>
          <acceleration>2.53881 -3.75269 -0.437072 3.09821 0.063887 0.001467</acceleration>
          <wrench>1269.4 -1876.34 -218.536 0 -0 0</wrench>
        </link>
      </model>
      <model name='Construction Barrel_2'>
        <pose>9.35809 3.98924 0.049999 3e-06 -0 0.000136</pose>
        <link name='link'>
          <pose>9.35809 3.98924 0.049999 3e-06 -0 0.000136</pose>
          <velocity>0 0 0 0 -0 0</velocity>
          <acceleration>2.02388 -3.60313 -0.663625 2.72563 -1.23044 0.007992</acceleration>
          <wrench>1011.94 -1801.56 -331.813 0 -0 0</wrench>
        </link>
      </model>
      <model name='Construction Barrel_3'>
        <pose>9.4102 -5.22658 0.049999 3e-06 -0 0.000142</pose>
        <link name='link'>
          <pose>9.4102 -5.22658 0.049999 3e-06 -0 0.000142</pose>
          <velocity>0 0 0 0 -0 0</velocity>
          <acceleration>1.99365 -3.59358 -0.670204 2.70288 -1.30844 0.009671</acceleration>
          <wrench>996.827 -1796.79 -335.102 0 -0 0</wrench>
        </link>
      </model>
      <model name='Construction Barrel_4'>
        <pose>9.4084 -2.22775 0.049999 -1e-06 -2e-06 8.1e-05</pose>
        <link name='link'>
          <pose>9.4084 -2.22775 0.049999 -1e-06 -2e-06 8.1e-05</pose>
          <velocity>0 0 0 0 -0 0</velocity>
          <acceleration>-2.00495 3.79752 0.740668 3.07228 1.27628 -0.005857</acceleration>
          <wrench>-1002.48 1898.76 370.334 0 -0 0</wrench>
        </link>
      </model>
      <model name='Construction Barrel_5'>
        <pose>9.39378 0.920461 0.049999 3e-06 -0 0.000135</pose>
        <link name='link'>
          <pose>9.39378 0.920461 0.049999 3e-06 -0 0.000135</pose>
          <velocity>0 0 0 0 -0 0</velocity>
          <acceleration>2.08359 -3.62235 -0.628167 2.77302 -1.07939 0.006535</acceleration>
          <wrench>1041.8 -1811.17 -314.083 0 -0 0</wrench>
        </link>
      </model>
      <model name='Construction Cone_0'>
        <pose>2.73889 0.581268 0.05 0 -1e-06 0</pose>
        <link name='link'>
          <pose>2.73889 0.581268 0.05 0 -1e-06 0</pose>
          <velocity>0 0 0 0 -0 0</velocity>
          <acceleration>0 0 0.833579 1.89675 0.576546 -3.14159</acceleration>
          <wrench>0 0 0.833579 0 -0 0</wrench>
        </link>
      </model>
      <model name='Construction Cone_1'>
        <pose>2.96648 3.01424 0.05 2e-06 -0 0.002903</pose>
        <link name='link'>
          <pose>2.96648 3.01424 0.05 2e-06 -0 0.002903</pose>
          <velocity>0 0 0 0 -0 0</velocity>
          <acceleration>1e-06 -1e-06 -2.25007 1.89472 1.29025 -0</acceleration>
          <wrench>1e-06 -1e-06 -2.25007 0 -0 0</wrench>
        </link>
      </model>
      <model name='Construction Cone_2'>
        <pose>0.479088 3.11332 0.04999 0 -0 0</pose>
        <link name='link'>
          <pose>0.479088 3.11332 0.04999 0 -0 0</pose>
          <velocity>0 0 0 0 -0 0</velocity>
          <acceleration>0 0 -9.8 0 -0 0</acceleration>
          <wrench>0 0 -9.8 0 -0 0</wrench>
        </link>
      </model>
      <model name='Construction Cone_3'>
        <pose>0.624482 0.551522 0.050001 1e-06 -3e-06 0</pose>
        <link name='link'>
          <pose>0.624482 0.551522 0.050001 1e-06 -3e-06 0</pose>
          <velocity>0 0 0 0 -0 0</velocity>
          <acceleration>0 1e-06 2.89645 0.98091 -0.051057 3.14159</acceleration>
          <wrench>0 1e-06 2.89645 0 -0 0</wrench>
        </link>
      </model>
      <model name='Lamp Post'>
        <pose>9.60908 8.80967 0 0 -0 0</pose>
        <link name='link'>
          <pose>9.60908 8.80967 0 0 -0 0</pose>
          <velocity>0 0 0 0 -0 0</velocity>
          <acceleration>0 0 0 0 -0 0</acceleration>
          <wrench>0 0 0 0 -0 0</wrench>
        </link>
      </model>
      <model name='Lamp Post_0'>
        <pose>-9.35588 8.4159 0 0 -0 0</pose>
        <link name='link'>
          <pose>-9.35588 8.4159 0 0 -0 0</pose>
          <velocity>0 0 0 0 -0 0</velocity>
          <acceleration>0 0 0 0 -0 0</acceleration>
          <wrench>0 0 0 0 -0 0</wrench>
        </link>
      </model>
      <model name='Lamp Post_1'>
        <pose>-9.24439 -8.71353 0 0 0 -2.93795</pose>
        <link name='link'>
          <pose>-9.24439 -8.71353 0 0 0 -2.93795</pose>
          <velocity>0 0 0 0 -0 0</velocity>
          <acceleration>0 0 0 0 -0 0</acceleration>
          <wrench>0 0 0 0 -0 0</wrench>
        </link>
      </model>
      <model name='Lamp Post_2'>
        <pose>9.3027 -8.68834 0 0 -0 3.07629</pose>
        <link name='link'>
          <pose>9.3027 -8.68834 0 0 -0 3.07629</pose>
          <velocity>0 0 0 0 -0 0</velocity>
          <acceleration>0 0 0 0 -0 0</acceleration>
          <wrench>0 0 0 0 -0 0</wrench>
        </link>
      </model>
      <model name='asphalt_plane'>
        <pose>0.080019 0.200751 0 0 -0 0</pose>
        <link name='link'>
          <pose>0.080019 0.200751 0 0 -0 0</pose>
          <velocity>0 0 0 0 -0 0</velocity>
          <acceleration>0 0 0 0 -0 0</acceleration>
          <wrench>0 0 0 0 -0 0</wrench>
        </link>
      </model>
      <model name='ground_plane'>
        <pose>0 0 0 0 -0 0</pose>
        <link name='link'>
          <pose>0 0 0 0 -0 0</pose>
          <velocity>0 0 0 0 -0 0</velocity>
          <acceleration>0 0 0 0 -0 0</acceleration>
          <wrench>0 0 0 0 -0 0</wrench>
        </link>
      </model>
      <model name='jersey_barrier'>
        <pose>-6.65745 -9.39618 0 0 -0 0</pose>
        <link name='link'>
          <pose>-6.65745 -9.39618 0 0 -0 0</pose>
          <velocity>0 0 0 0 -0 0</velocity>
          <acceleration>0 0 0 0 -0 0</acceleration>
          <wrench>0 0 0 0 -0 0</wrench>
        </link>
      </model>
      <model name='jersey_barrier_0'>
        <pose>-1.8345 -9.38062 0 0 -0 0</pose>
        <link name='link'>
          <pose>-1.8345 -9.38062 0 0 -0 0</pose>
          <velocity>0 0 0 0 -0 0</velocity>
          <acceleration>0 0 0 0 -0 0</acceleration>
          <wrench>0 0 0 0 -0 0</wrench>
        </link>
      </model>
      <model name='jersey_barrier_1'>
        <pose>2.81184 -9.40291 0 0 -0 0</pose>
        <link name='link'>
          <pose>2.81184 -9.40291 0 0 -0 0</pose>
          <velocity>0 0 0 0 -0 0</velocity>
          <acceleration>0 0 0 0 -0 0</acceleration>
          <wrench>0 0 0 0 -0 0</wrench>
        </link>
      </model>
      <model name='jersey_barrier_2'>
        <pose>7.4313 -9.37927 0 0 -0 0</pose>
        <link name='link'>
          <pose>7.4313 -9.37927 0 0 -0 0</pose>
          <velocity>0 0 0 0 -0 0</velocity>
          <acceleration>0 0 0 0 -0 0</acceleration>
          <wrench>0 0 0 0 -0 0</wrench>
        </link>
      </model>
      <model name='jersey_barrier_3'>
        <pose>-7.11244 9.11903 0 0 -0 0</pose>
        <link name='link'>
          <pose>-7.11244 9.11903 0 0 -0 0</pose>
          <velocity>0 0 0 0 -0 0</velocity>
          <acceleration>0 0 0 0 -0 0</acceleration>
          <wrench>0 0 0 0 -0 0</wrench>
        </link>
      </model>
      <model name='jersey_barrier_4'>
        <pose>-2.47812 9.32762 0 0 -0 0</pose>
        <link name='link'>
          <pose>-2.47812 9.32762 0 0 -0 0</pose>
          <velocity>0 0 0 0 -0 0</velocity>
          <acceleration>0 0 0 0 -0 0</acceleration>
          <wrench>0 0 0 0 -0 0</wrench>
        </link>
      </model>
      <model name='jersey_barrier_5'>
        <pose>2.29939 9.37988 0 0 -0 0</pose>
        <link name='link'>
          <pose>2.29939 9.37988 0 0 -0 0</pose>
          <velocity>0 0 0 0 -0 0</velocity>
          <acceleration>0 0 0 0 -0 0</acceleration>
          <wrench>0 0 0 0 -0 0</wrench>
        </link>
      </model>
      <model name='jersey_barrier_6'>
        <pose>6.90559 9.44069 0 0 -0 0</pose>
        <link name='link'>
          <pose>6.90559 9.44069 0 0 -0 0</pose>
          <velocity>0 0 0 0 -0 0</velocity>
          <acceleration>0 0 0 0 -0 0</acceleration>
          <wrench>0 0 0 0 -0 0</wrench>
        </link>
      </model>
      <model name='polaris_ranger_ev'>
        <pose>-6.02512 5.34319 0.050271 -9.3e-05 5.9e-05 -0.007644</pose>
        <link name='FNR_switch'>
          <pose>-5.46522 5.31901 1.13024 -9.4e-05 -0.049941 -0.007639</pose>
          <velocity>-0.000817 -0.003673 -0.005983 0.004592 -0.001725 -0.000347</velocity>
          <acceleration>-2e-06 2e-06 1e-06 -0.000163 -0.020862 -6e-06</acceleration>
          <wrench>0 0 0 0 -0 0</wrench>
        </link>
        <link name='brake_pedal'>
          <pose>-5.31444 5.60781 0.589044 -9.4e-05 6.1e-05 -0.007644</pose>
          <velocity>0.000269 -0.001241 -0.004365 0.004637 -0.001945 -0.00035</velocity>
          <acceleration>-1e-06 1e-06 1e-06 -3e-06 -2e-06 0</acceleration>
          <wrench>0 0 0 0 -0 0</wrench>
        </link>
        <link name='chassis'>
          <pose>-6.02512 5.34319 0.050271 -9.3e-05 5.9e-05 -0.007644</pose>
          <velocity>0.001176 0.001456 -0.006916 0.004548 -0.001828 -0.000345</velocity>
          <acceleration>-1e-06 0 0 -3e-06 -3e-06 6e-06</acceleration>
          <wrench>-0.00071 0.000137 0.000275 0 -0 0</wrench>
        </link>
        <link name='front_left_wheel'>
          <pose>-4.97098 5.93324 0.370235 1.4927 -0.886828 2.99809</pose>
          <velocity>0.000666 -0.001075 -0.011041 0.005046 0.001792 -7.9e-05</velocity>
          <acceleration>-1e-06 0 0 -1e-06 -2e-06 0</acceleration>
          <wrench>-1.7e-05 4e-06 1e-06 0 -0 0</wrench>
        </link>
        <link name='front_left_wheel_steering_block'>
          <pose>-4.9913 5.83533 0.370269 1.5707 4e-05 -0.20473</pose>
          <velocity>0.000637 -0.00108 -0.013981 0.004217 -0.001758 -0.000284</velocity>
          <acceleration>-1e-06 0 0 -3e-06 -2e-06 0</acceleration>
          <wrench>-1e-06 0 0 0 -0 0</wrench>
        </link>
        <link name='front_right_wheel'>
          <pose>-5.01837 4.73727 0.370283 -1.49544 -0.85379 2.88867</pose>
          <velocity>0.000187 -0.001262 -0.006022 0.003038 0.000841 -0.000524</velocity>
          <acceleration>-1e-06 1e-06 -3e-06 -3e-06 -2e-06 1e-06</acceleration>
          <wrench>-1.5e-05 7e-06 -3.5e-05 0 -0 0</wrench>
        </link>
        <link name='front_right_wheel_steering_block'>
          <pose>-4.99895 4.83536 0.370278 1.5707 4.1e-05 -0.195441</pose>
          <velocity>0.000219 -0.001272 -0.00504 0.004295 -0.001791 -0.000398</velocity>
          <acceleration>-1e-06 1e-06 -5e-06 -2e-06 -2e-06 0</acceleration>
          <wrench>-1e-06 1e-06 -5e-06 0 -0 0</wrench>
        </link>
        <link name='gas_pedal'>
          <pose>-5.33777 5.43798 0.573652 -9.4e-05 6e-05 -0.007644</pose>
          <velocity>0.00024 -0.001162 -0.005197 0.004604 -0.00192 -0.000347</velocity>
          <acceleration>-1e-06 1e-06 1e-06 -3e-06 -2e-06 0</acceleration>
          <wrench>0 0 0 0 -0 0</wrench>
        </link>
        <link name='hand_brake'>
          <pose>-5.49453 5.40923 1.10023 -0.000113 -0.599941 -0.00758</pose>
          <velocity>-0.000731 -0.003525 -0.005623 0.004598 -0.001526 -0.000353</velocity>
          <acceleration>-2e-06 2e-06 1e-06 -2.5e-05 -0.003048 4e-06</acceleration>
          <wrench>-1e-06 1e-06 1e-06 0 -0 0</wrench>
        </link>
        <link name='rear_left_wheel'>
          <pose>-6.87049 5.9497 0.370264 1.50346 -0.749517 -3.10275</pose>
          <velocity>0.000808 -0.000103 -0.005504 0.001138 0.002452 -0.000101</velocity>
          <acceleration>-1e-06 0 -2e-06 -0.000249 -0.035047 -0.017723</acceleration>
          <wrench>-1.2e-05 4e-06 -2.3e-05 0 -0 0</wrench>
        </link>
        <link name='rear_right_wheel'>
          <pose>-6.87971 4.74973 0.370232 -1.50471 -0.726194 3.08947</pose>
          <velocity>0.000384 -0.000305 -0.011257 -0.000774 0.001338 -0.000511</velocity>
          <acceleration>-1e-06 0 1e-06 0.000295 0.035964 0.007187</acceleration>
          <wrench>-9e-06 -4e-06 1.6e-05 0 -0 0</wrench>
        </link>
        <link name='steering_wheel'>
          <pose>-5.68429 5.63874 1.33842 0.86215 0.135155 -1.69351</pose>
          <velocity>-0.00109 -0.004553 -0.004919 0.004565 -0.001844 -0.000325</velocity>
          <acceleration>-3e-06 3e-06 0 -6e-06 -1.2e-05 -2e-06</acceleration>
          <wrench>-3e-06 3e-06 0 0 -0 0</wrench>
        </link>
      </model>
      <light name='sun'>
        <pose>0 0 10 0 -0 0</pose>
      </light>
    </state>
    <gui fullscreen='0'>
      <camera name='user_camera'>
        <pose>13.7605 -7.15694 18.8324 0 0.807388 2.35107</pose>
        <view_controller>orbit</view_controller>
        <projection_type>perspective</projection_type>
      </camera>
    </gui>
    <wind/>
    <model name='asphalt_plane'>
      <static>1</static>
      <link name='link'>
        <collision name='collision'>
          <geometry>
            <box>
              <size>20 20 0.1</size>
            </box>
          </geometry>
          <surface>
            <friction>
              <ode>
                <mu>100</mu>
                <mu2>50</mu2>
              </ode>
              <torsional>
                <ode/>
              </torsional>
            </friction>
            <contact>
              <ode/>
            </contact>
            <bounce/>
          </surface>
          <max_contacts>10</max_contacts>
        </collision>
        <visual name='visual'>
          <cast_shadows>0</cast_shadows>
          <geometry>
            <box>
              <size>20 20 0.1</size>
            </box>
          </geometry>
          <material>
            <script>
              <uri>model://asphalt_plane/materials/scripts</uri>
              <uri>model://asphalt_plane/materials/textures</uri>
              <name>vrc/asphalt</name>
            </script>
          </material>
        </visual>
        <self_collide>0</self_collide>
        <enable_wind>0</enable_wind>
        <kinematic>0</kinematic>
        <gravity>1</gravity>
      </link>
      <pose>0.023989 -0.013318 0 0 -0 0</pose>
    </model>
    <model name='polaris_ranger_ev'>
      <link name='chassis'>
        <inertial>
          <mass>720</mass>
          <inertia>
            <ixx>140</ixx>
            <ixy>0</ixy>
            <iyy>550</iyy>
            <ixz>0</ixz>
            <iyz>0</iyz>
            <izz>550</izz>
          </inertia>
          <pose>0.1 0 0.4 0 -0 0</pose>
        </inertial>
        <visual name='visual'>
          <pose>0 0 0 0 0 -1.5708</pose>
          <geometry>
            <mesh>
              <uri>model://polaris_ranger_ev/meshes/polaris.dae</uri>
              <submesh>
                <name>Ranger</name>
                <center>0</center>
              </submesh>
            </mesh>
          </geometry>
          <material>
            <script>
              <uri>model://polaris_ranger_ev/materials/scripts</uri>
              <uri>model://polaris_ranger_ev/materials/textures</uri>
              <name>Polaris/Diffuse</name>
            </script>
          </material>
        </visual>
        <collision name='chassis_bottom'>
          <pose>0.1 0 0.37 0 -0 0</pose>
          <geometry>
            <box>
              <size>1.5 1.34 0.06</size>
            </box>
          </geometry>
          <max_contacts>10</max_contacts>
          <surface>
            <contact>
              <ode/>
            </contact>
            <bounce/>
            <friction>
              <torsional>
                <ode/>
              </torsional>
              <ode/>
            </friction>
          </surface>
        </collision>
        <collision name='cargo_bottom'>
          <pose>-0.9 0 0.9 0 -0 0</pose>
          <geometry>
            <box>
              <size>0.9 1.2 0.01</size>
            </box>
          </geometry>
          <max_contacts>10</max_contacts>
          <surface>
            <contact>
              <ode/>
            </contact>
            <bounce/>
            <friction>
              <torsional>
                <ode/>
              </torsional>
              <ode/>
            </friction>
          </surface>
        </collision>
        <collision name='cargo_front'>
          <pose>-0.45 0 1.025 0 -0 0</pose>
          <geometry>
            <box>
              <size>0.05 1.2 0.25</size>
            </box>
          </geometry>
          <max_contacts>10</max_contacts>
          <surface>
            <contact>
              <ode/>
            </contact>
            <bounce/>
            <friction>
              <torsional>
                <ode/>
              </torsional>
              <ode/>
            </friction>
          </surface>
        </collision>
        <collision name='cargo_back'>
          <pose>-1.35 0 1.025 0 -0 0</pose>
          <geometry>
            <box>
              <size>0.05 1.2 0.25</size>
            </box>
          </geometry>
          <max_contacts>10</max_contacts>
          <surface>
            <contact>
              <ode/>
            </contact>
            <bounce/>
            <friction>
              <torsional>
                <ode/>
              </torsional>
              <ode/>
            </friction>
          </surface>
        </collision>
        <collision name='cargo_left'>
          <pose>-0.9 0.6 1.025 0 -0 0</pose>
          <geometry>
            <box>
              <size>0.9 0.05 0.25</size>
            </box>
          </geometry>
          <max_contacts>10</max_contacts>
          <surface>
            <contact>
              <ode/>
            </contact>
            <bounce/>
            <friction>
              <torsional>
                <ode/>
              </torsional>
              <ode/>
            </friction>
          </surface>
        </collision>
        <collision name='cargo_right'>
          <pose>-0.9 -0.6 1.025 0 -0 0</pose>
          <geometry>
            <box>
              <size>0.9 0.05 0.25</size>
            </box>
          </geometry>
          <max_contacts>10</max_contacts>
          <surface>
            <contact>
              <ode/>
            </contact>
            <bounce/>
            <friction>
              <torsional>
                <ode/>
              </torsional>
              <ode/>
            </friction>
          </surface>
        </collision>
        <collision name='seat'>
          <pose>-0.1 0 0.56 0 -0 0</pose>
          <geometry>
            <box>
              <size>0.6 1.22 0.5</size>
            </box>
          </geometry>
          <surface>
            <contact>
              <ode>
                <min_depth>0.01</min_depth>
              </ode>
            </contact>
            <bounce/>
            <friction>
              <torsional>
                <ode/>
              </torsional>
              <ode/>
            </friction>
          </surface>
          <max_contacts>10</max_contacts>
        </collision>
        <collision name='mud_seat'>
          <pose>-0.1 0 0.81 0 -0 0</pose>
          <geometry>
            <box>
              <size>0.6 1.15 0.1</size>
            </box>
          </geometry>
          <surface>
            <contact>
              <collide_without_contact>1</collide_without_contact>
              <ode/>
            </contact>
            <bounce/>
            <friction>
              <torsional>
                <ode/>
              </torsional>
              <ode/>
            </friction>
          </surface>
          <max_contacts>10</max_contacts>
        </collision>
        <sensor name='seat_contact' type='contact'>
          <always_on>1</always_on>
          <update_rate>1000</update_rate>
          <contact>
            <collision>mud_seat</collision>
            <topic>__default_topic__</topic>
          </contact>
        </sensor>
        <collision name='seat_back'>
          <pose>-0.3 0 1.125 0 -0.2 0</pose>
          <geometry>
            <box>
              <size>0.06 1 0.4</size>
            </box>
          </geometry>
          <max_contacts>10</max_contacts>
          <surface>
            <contact>
              <ode/>
            </contact>
            <bounce/>
            <friction>
              <torsional>
                <ode/>
              </torsional>
              <ode/>
            </friction>
          </surface>
        </collision>
        <collision name='engine'>
          <pose>1.05 0 0.7 0 -0 0</pose>
          <geometry>
            <box>
              <size>0.58 1 0.8</size>
            </box>
          </geometry>
          <max_contacts>10</max_contacts>
          <surface>
            <contact>
              <ode/>
            </contact>
            <bounce/>
            <friction>
              <torsional>
                <ode/>
              </torsional>
              <ode/>
            </friction>
          </surface>
        </collision>
        <collision name='handle_left_middle'>
          <pose>-0.3 0.61 1.055 0 -0.2 0</pose>
          <geometry>
            <cylinder>
              <radius>0.02</radius>
              <length>0.17</length>
            </cylinder>
          </geometry>
          <max_contacts>10</max_contacts>
          <surface>
            <contact>
              <ode/>
            </contact>
            <bounce/>
            <friction>
              <torsional>
                <ode/>
              </torsional>
              <ode/>
            </friction>
          </surface>
        </collision>
        <collision name='handle_right_middle'>
          <pose>-0.3 -0.61 1.055 0 -0.2 0</pose>
          <geometry>
            <cylinder>
              <radius>0.02</radius>
              <length>0.17</length>
            </cylinder>
          </geometry>
          <max_contacts>10</max_contacts>
          <surface>
            <contact>
              <ode/>
            </contact>
            <bounce/>
            <friction>
              <torsional>
                <ode/>
              </torsional>
              <ode/>
            </friction>
          </surface>
        </collision>
        <collision name='rollcage_top_left'>
          <pose>0 0.61 1.92 3.14159 1.53159 3.14159</pose>
          <geometry>
            <cylinder>
              <radius>0.03</radius>
              <length>0.68</length>
            </cylinder>
          </geometry>
          <max_contacts>10</max_contacts>
          <surface>
            <contact>
              <ode/>
            </contact>
            <bounce/>
            <friction>
              <torsional>
                <ode/>
              </torsional>
              <ode/>
            </friction>
          </surface>
        </collision>
        <collision name='rollcage_top_right'>
          <pose>0 -0.61 1.92 3.14159 1.53159 3.14159</pose>
          <geometry>
            <cylinder>
              <radius>0.03</radius>
              <length>0.68</length>
            </cylinder>
          </geometry>
          <max_contacts>10</max_contacts>
          <surface>
            <contact>
              <ode/>
            </contact>
            <bounce/>
            <friction>
              <torsional>
                <ode/>
              </torsional>
              <ode/>
            </friction>
          </surface>
        </collision>
        <collision name='rollcage_top_front'>
          <pose>0.325 0 1.89 1.5708 -0 0</pose>
          <geometry>
            <cylinder>
              <radius>0.03</radius>
              <length>1.22</length>
            </cylinder>
          </geometry>
          <max_contacts>10</max_contacts>
          <surface>
            <contact>
              <ode/>
            </contact>
            <bounce/>
            <friction>
              <torsional>
                <ode/>
              </torsional>
              <ode/>
            </friction>
          </surface>
        </collision>
        <collision name='rollcage_top_back'>
          <pose>-0.33 0 1.92 1.5708 -0 0</pose>
          <geometry>
            <cylinder>
              <radius>0.03</radius>
              <length>1.22</length>
            </cylinder>
          </geometry>
          <max_contacts>10</max_contacts>
          <surface>
            <contact>
              <ode/>
            </contact>
            <bounce/>
            <friction>
              <torsional>
                <ode/>
              </torsional>
              <ode/>
            </friction>
          </surface>
        </collision>
        <collision name='rollcage_front_left'>
          <pose>0.54 0.61 1.45 0 -0.44 0</pose>
          <geometry>
            <cylinder>
              <radius>0.03</radius>
              <length>1.04</length>
            </cylinder>
          </geometry>
          <max_contacts>10</max_contacts>
          <surface>
            <contact>
              <ode/>
            </contact>
            <bounce/>
            <friction>
              <torsional>
                <ode/>
              </torsional>
              <ode/>
            </friction>
          </surface>
        </collision>
        <collision name='rollcage_front_right'>
          <pose>0.54 -0.61 1.45 0 -0.44 0</pose>
          <geometry>
            <cylinder>
              <radius>0.03</radius>
              <length>1.04</length>
            </cylinder>
          </geometry>
          <max_contacts>10</max_contacts>
          <surface>
            <contact>
              <ode/>
            </contact>
            <bounce/>
            <friction>
              <torsional>
                <ode/>
              </torsional>
              <ode/>
            </friction>
          </surface>
        </collision>
        <collision name='fender_front_right'>
          <pose>0.64 -0.61 0.7 0 0.35 0</pose>
          <geometry>
            <cylinder>
              <radius>0.03</radius>
              <length>0.72</length>
            </cylinder>
          </geometry>
          <max_contacts>10</max_contacts>
          <surface>
            <contact>
              <ode/>
            </contact>
            <bounce/>
            <friction>
              <torsional>
                <ode/>
              </torsional>
              <ode/>
            </friction>
          </surface>
        </collision>
        <collision name='fender_front_left'>
          <pose>0.64 0.61 0.7 0 0.35 0</pose>
          <geometry>
            <cylinder>
              <radius>0.03</radius>
              <length>0.72</length>
            </cylinder>
          </geometry>
          <max_contacts>10</max_contacts>
          <surface>
            <contact>
              <ode/>
            </contact>
            <bounce/>
            <friction>
              <torsional>
                <ode/>
              </torsional>
              <ode/>
            </friction>
          </surface>
        </collision>
        <collision name='rollcage_back_left'>
          <pose>-0.37 0.61 1.25 0 -0.14 0</pose>
          <geometry>
            <cylinder>
              <radius>0.03</radius>
              <length>0.9</length>
            </cylinder>
          </geometry>
          <max_contacts>10</max_contacts>
          <surface>
            <contact>
              <ode/>
            </contact>
            <bounce/>
            <friction>
              <torsional>
                <ode/>
              </torsional>
              <ode/>
            </friction>
          </surface>
        </collision>
        <collision name='rollcage_back_right'>
          <pose>-0.37 -0.61 1.25 0 -0.14 0</pose>
          <geometry>
            <cylinder>
              <radius>0.03</radius>
              <length>0.9</length>
            </cylinder>
          </geometry>
          <max_contacts>10</max_contacts>
          <surface>
            <contact>
              <ode/>
            </contact>
            <bounce/>
            <friction>
              <torsional>
                <ode/>
              </torsional>
              <ode/>
            </friction>
          </surface>
        </collision>
        <collision name='rollcage_back_midleft'>
          <pose>-0.37 0.155 1.25 0 -0.14 0</pose>
          <geometry>
            <cylinder>
              <radius>0.023</radius>
              <length>0.9</length>
            </cylinder>
          </geometry>
          <max_contacts>10</max_contacts>
          <surface>
            <contact>
              <ode/>
            </contact>
            <bounce/>
            <friction>
              <torsional>
                <ode/>
              </torsional>
              <ode/>
            </friction>
          </surface>
        </collision>
        <collision name='rollcage_back_midright'>
          <pose>-0.37 -0.155 1.25 0 -0.14 0</pose>
          <geometry>
            <cylinder>
              <radius>0.023</radius>
              <length>0.9</length>
            </cylinder>
          </geometry>
          <max_contacts>10</max_contacts>
          <surface>
            <contact>
              <ode/>
            </contact>
            <bounce/>
            <friction>
              <torsional>
                <ode/>
              </torsional>
              <ode/>
            </friction>
          </surface>
        </collision>
        <collision name='rollcage_back_upper_left'>
          <pose>-0.38 0.61 1.82 0 0.4 0</pose>
          <geometry>
            <cylinder>
              <radius>0.03</radius>
              <length>0.29</length>
            </cylinder>
          </geometry>
          <max_contacts>10</max_contacts>
          <surface>
            <contact>
              <ode/>
            </contact>
            <bounce/>
            <friction>
              <torsional>
                <ode/>
              </torsional>
              <ode/>
            </friction>
          </surface>
        </collision>
        <collision name='rollcage_back_upper_right'>
          <pose>-0.38 -0.61 1.82 0 0.4 0</pose>
          <geometry>
            <cylinder>
              <radius>0.03</radius>
              <length>0.29</length>
            </cylinder>
          </geometry>
          <max_contacts>10</max_contacts>
          <surface>
            <contact>
              <ode/>
            </contact>
            <bounce/>
            <friction>
              <torsional>
                <ode/>
              </torsional>
              <ode/>
            </friction>
          </surface>
        </collision>
        <collision name='rollcage_back_upper_midleft'>
          <pose>-0.38 0.155 1.82 0 0.4 0</pose>
          <geometry>
            <cylinder>
              <radius>0.023</radius>
              <length>0.29</length>
            </cylinder>
          </geometry>
          <max_contacts>10</max_contacts>
          <surface>
            <contact>
              <ode/>
            </contact>
            <bounce/>
            <friction>
              <torsional>
                <ode/>
              </torsional>
              <ode/>
            </friction>
          </surface>
        </collision>
        <collision name='rollcage_back_upper_midright'>
          <pose>-0.38 -0.155 1.82 0 0.4 0</pose>
          <geometry>
            <cylinder>
              <radius>0.023</radius>
              <length>0.29</length>
            </cylinder>
          </geometry>
          <max_contacts>10</max_contacts>
          <surface>
            <contact>
              <ode/>
            </contact>
            <bounce/>
            <friction>
              <torsional>
                <ode/>
              </torsional>
              <ode/>
            </friction>
          </surface>
        </collision>
        <self_collide>0</self_collide>
        <enable_wind>0</enable_wind>
        <kinematic>0</kinematic>
        <gravity>1</gravity>
      </link>
      <link name='rear_right_wheel'>
        <pose>-0.85 -0.6 0.32 1.52 -0 0</pose>
        <inertial>
          <mass>12</mass>
          <inertia>
            <ixx>0.5</ixx>
            <ixy>0</ixy>
            <iyy>0.5</iyy>
            <ixz>0</ixz>
            <iyz>0</iyz>
            <izz>1</izz>
          </inertia>
        </inertial>
        <collision name='collision'>
          <geometry>
            <cylinder>
              <radius>0.32</radius>
              <length>0.23</length>
            </cylinder>
          </geometry>
          <max_contacts>1</max_contacts>
          <surface>
            <friction>
              <ode>
                <mu>1</mu>
                <mu2>1</mu2>
                <fdir1>0 0 1</fdir1>
                <slip1>0</slip1>
                <slip2>0</slip2>
              </ode>
              <torsional>
                <ode/>
              </torsional>
            </friction>
            <contact>
              <ode>
                <min_depth>0.005</min_depth>
                <kp>1e+08</kp>
              </ode>
            </contact>
            <bounce/>
          </surface>
        </collision>
        <visual name='visual'>
          <pose>0 0 0 3.14159 -1.57079 3.14159</pose>
          <geometry>
            <mesh>
              <uri>model://polaris_ranger_ev/meshes/polaris.dae</uri>
              <submesh>
                <name>Rear_Wheel_Right</name>
                <center>1</center>
              </submesh>
            </mesh>
          </geometry>
          <material>
            <script>
              <uri>model://polaris_ranger_ev/materials/scripts</uri>
              <uri>model://polaris_ranger_ev/materials/textures</uri>
              <name>Polaris/Diffuse</name>
            </script>
          </material>
        </visual>
        <self_collide>0</self_collide>
        <enable_wind>0</enable_wind>
        <kinematic>0</kinematic>
        <gravity>1</gravity>
      </link>
      <link name='rear_left_wheel'>
        <pose>-0.85 0.6 0.32 -1.52 0 0</pose>
        <inertial>
          <mass>12</mass>
          <inertia>
            <ixx>0.5</ixx>
            <ixy>0</ixy>
            <iyy>0.5</iyy>
            <ixz>0</ixz>
            <iyz>0</iyz>
            <izz>1</izz>
          </inertia>
        </inertial>
        <collision name='collision'>
          <geometry>
            <cylinder>
              <radius>0.32</radius>
              <length>0.23</length>
            </cylinder>
          </geometry>
          <max_contacts>1</max_contacts>
          <surface>
            <friction>
              <ode>
                <mu>1</mu>
                <mu2>1</mu2>
                <fdir1>0 0 1</fdir1>
                <slip1>0</slip1>
                <slip2>0</slip2>
              </ode>
              <torsional>
                <ode/>
              </torsional>
            </friction>
            <contact>
              <ode>
                <min_depth>0.005</min_depth>
                <kp>1e+08</kp>
              </ode>
            </contact>
            <bounce/>
          </surface>
        </collision>
        <visual name='visual'>
          <pose>0 0 0 3.14159 -1.57079 3.14159</pose>
          <geometry>
            <mesh>
              <uri>model://polaris_ranger_ev/meshes/polaris.dae</uri>
              <submesh>
                <name>Rear_Wheel_Left</name>
                <center>1</center>
              </submesh>
            </mesh>
          </geometry>
          <material>
            <script>
              <uri>model://polaris_ranger_ev/materials/scripts</uri>
              <uri>model://polaris_ranger_ev/materials/textures</uri>
              <name>Polaris/Diffuse</name>
            </script>
          </material>
        </visual>
        <self_collide>0</self_collide>
        <enable_wind>0</enable_wind>
        <kinematic>0</kinematic>
        <gravity>1</gravity>
      </link>
      <link name='front_right_wheel'>
        <pose>1.03 -0.6 0.32 1.52 -0 0</pose>
        <inertial>
          <mass>12</mass>
          <inertia>
            <ixx>0.5</ixx>
            <ixy>0</ixy>
            <iyy>0.5</iyy>
            <ixz>0</ixz>
            <iyz>0</iyz>
            <izz>1</izz>
          </inertia>
        </inertial>
        <collision name='collision'>
          <geometry>
            <cylinder>
              <radius>0.32</radius>
              <length>0.23</length>
            </cylinder>
          </geometry>
          <max_contacts>1</max_contacts>
          <surface>
            <friction>
              <ode>
                <mu>1</mu>
                <mu2>1</mu2>
                <fdir1>0 0 1</fdir1>
                <slip1>0</slip1>
                <slip2>0</slip2>
              </ode>
              <torsional>
                <ode/>
              </torsional>
            </friction>
            <contact>
              <ode>
                <min_depth>0.005</min_depth>
                <kp>1e+08</kp>
              </ode>
            </contact>
            <bounce/>
          </surface>
        </collision>
        <visual name='visual'>
          <pose>0 0 0 3.14159 -1.57079 3.14159</pose>
          <geometry>
            <mesh>
              <uri>model://polaris_ranger_ev/meshes/polaris.dae</uri>
              <submesh>
                <name>Front_Wheel_Right</name>
                <center>1</center>
              </submesh>
            </mesh>
          </geometry>
          <material>
            <script>
              <uri>model://polaris_ranger_ev/materials/scripts</uri>
              <uri>model://polaris_ranger_ev/materials/textures</uri>
              <name>Polaris/Diffuse</name>
            </script>
          </material>
        </visual>
        <self_collide>0</self_collide>
        <enable_wind>0</enable_wind>
        <kinematic>0</kinematic>
        <gravity>1</gravity>
      </link>
      <link name='front_right_wheel_steering_block'>
        <pose>1.03 -0.5 0.32 1.5708 -0 0</pose>
        <inertial>
          <mass>1</mass>
          <inertia>
            <ixx>1</ixx>
            <ixy>0</ixy>
            <iyy>1</iyy>
            <ixz>0</ixz>
            <iyz>0</iyz>
            <izz>1</izz>
          </inertia>
        </inertial>
        <collision name='collision'>
          <geometry>
            <cylinder>
              <radius>0.05</radius>
              <length>0.01</length>
            </cylinder>
          </geometry>
          <max_contacts>10</max_contacts>
          <surface>
            <contact>
              <ode/>
            </contact>
            <bounce/>
            <friction>
              <torsional>
                <ode/>
              </torsional>
              <ode/>
            </friction>
          </surface>
        </collision>
        <self_collide>0</self_collide>
        <enable_wind>0</enable_wind>
        <kinematic>0</kinematic>
        <gravity>1</gravity>
      </link>
      <link name='front_left_wheel'>
        <pose>1.03 0.6 0.32 -1.52 0 0</pose>
        <inertial>
          <mass>12</mass>
          <inertia>
            <ixx>0.5</ixx>
            <ixy>0</ixy>
            <iyy>0.5</iyy>
            <ixz>0</ixz>
            <iyz>0</iyz>
            <izz>1</izz>
          </inertia>
        </inertial>
        <collision name='collision'>
          <geometry>
            <cylinder>
              <radius>0.32</radius>
              <length>0.23</length>
            </cylinder>
          </geometry>
          <max_contacts>1</max_contacts>
          <surface>
            <friction>
              <ode>
                <mu>1</mu>
                <mu2>1</mu2>
                <fdir1>0 0 1</fdir1>
                <slip1>0</slip1>
                <slip2>0</slip2>
              </ode>
              <torsional>
                <ode/>
              </torsional>
            </friction>
            <contact>
              <ode>
                <min_depth>0.005</min_depth>
                <kp>1e+08</kp>
              </ode>
            </contact>
            <bounce/>
          </surface>
        </collision>
        <visual name='visual'>
          <pose>0 0 0 -3e-06 1.57079 3.14159</pose>
          <geometry>
            <mesh>
              <uri>model://polaris_ranger_ev/meshes/polaris.dae</uri>
              <submesh>
                <name>Front_Wheel_Left</name>
                <center>1</center>
              </submesh>
            </mesh>
          </geometry>
          <material>
            <script>
              <uri>model://polaris_ranger_ev/materials/scripts</uri>
              <uri>model://polaris_ranger_ev/materials/textures</uri>
              <name>Polaris/Diffuse</name>
            </script>
          </material>
        </visual>
        <self_collide>0</self_collide>
        <enable_wind>0</enable_wind>
        <kinematic>0</kinematic>
        <gravity>1</gravity>
      </link>
      <link name='front_left_wheel_steering_block'>
        <pose>1.03 0.5 0.32 1.5708 -0 0</pose>
        <inertial>
          <mass>1</mass>
          <inertia>
            <ixx>1</ixx>
            <ixy>0</ixy>
            <iyy>1</iyy>
            <ixz>0</ixz>
            <iyz>0</iyz>
            <izz>1</izz>
          </inertia>
        </inertial>
        <collision name='collision'>
          <geometry>
            <cylinder>
              <radius>0.05</radius>
              <length>0.01</length>
            </cylinder>
          </geometry>
          <max_contacts>10</max_contacts>
          <surface>
            <contact>
              <ode/>
            </contact>
            <bounce/>
            <friction>
              <torsional>
                <ode/>
              </torsional>
              <ode/>
            </friction>
          </surface>
        </collision>
        <self_collide>0</self_collide>
        <enable_wind>0</enable_wind>
        <kinematic>0</kinematic>
        <gravity>1</gravity>
      </link>
      <link name='gas_pedal'>
        <pose>0.63 0.1 0.58 0 -0 0</pose>
        <gravity>0</gravity>
        <inertial>
          <mass>0.1</mass>
          <pose>0 0 0 0 -0 0</pose>
          <inertia>
            <ixx>0.01</ixx>
            <ixy>0</ixy>
            <ixz>0</ixz>
            <iyy>0.01</iyy>
            <iyz>0</iyz>
            <izz>0.01</izz>
          </inertia>
        </inertial>
        <collision name='gas_pedal_collision'>
          <pose>-0.0385 0 -0.086 3.14159 1.12559 3.14159</pose>
          <geometry>
            <box>
              <size>0.1069 0.077 0.01</size>
            </box>
          </geometry>
          <max_contacts>10</max_contacts>
          <surface>
            <contact>
              <ode/>
            </contact>
            <bounce/>
            <friction>
              <torsional>
                <ode/>
              </torsional>
              <ode/>
            </friction>
          </surface>
        </collision>
        <visual name='visual'>
          <pose>0 0 0 0 0 -1.5707</pose>
          <geometry>
            <mesh>
              <uri>model://polaris_ranger_ev/meshes/polaris.dae</uri>
              <submesh>
                <name>Pedal_Gas</name>
                <center>1</center>
              </submesh>
            </mesh>
          </geometry>
          <material>
            <script>
              <uri>model://polaris_ranger_ev/materials/scripts</uri>
              <uri>model://polaris_ranger_ev/materials/textures</uri>
              <name>Polaris/Diffuse</name>
            </script>
          </material>
        </visual>
        <self_collide>0</self_collide>
        <enable_wind>0</enable_wind>
        <kinematic>0</kinematic>
      </link>
      <link name='brake_pedal'>
        <gravity>0</gravity>
        <pose>0.64 0.27 0.58 0 -0 0</pose>
        <inertial>
          <mass>0.1</mass>
          <pose>0 0 0 0 -0 0</pose>
          <inertia>
            <ixx>0.01</ixx>
            <ixy>0</ixy>
            <ixz>0</ixz>
            <iyy>0.01</iyy>
            <iyz>0</iyz>
            <izz>0.01</izz>
          </inertia>
        </inertial>
        <collision name='brake_pedal_collision'>
          <pose>-0.04 0 -0.086 3.14159 1.14259 3.14159</pose>
          <geometry>
            <box>
              <size>0.063 0.08 0.01</size>
            </box>
          </geometry>
          <max_contacts>10</max_contacts>
          <surface>
            <contact>
              <ode/>
            </contact>
            <bounce/>
            <friction>
              <torsional>
                <ode/>
              </torsional>
              <ode/>
            </friction>
          </surface>
        </collision>
        <visual name='visual'>
          <pose>0 0 0 0 0 -1.5707</pose>
          <geometry>
            <mesh>
              <uri>model://polaris_ranger_ev/meshes/polaris.dae</uri>
              <submesh>
                <name>Pedal_brake</name>
                <center>1</center>
              </submesh>
            </mesh>
          </geometry>
          <material>
            <script>
              <uri>model://polaris_ranger_ev/materials/scripts</uri>
              <uri>model://polaris_ranger_ev/materials/textures</uri>
              <name>Polaris/Diffuse</name>
            </script>
          </material>
        </visual>
        <self_collide>0</self_collide>
        <enable_wind>0</enable_wind>
        <kinematic>0</kinematic>
      </link>
      <link name='steering_wheel'>
        <pose>0.34 0.3 1.29 0 -0.87 0</pose>
        <inertial>
          <mass>1</mass>
          <pose>-0.002 0 0 0 -0 0</pose>
          <inertia>
            <ixx>0.012</ixx>
            <ixy>0</ixy>
            <ixz>0</ixz>
            <iyy>0.012</iyy>
            <iyz>0</iyz>
            <izz>0.024</izz>
          </inertia>
        </inertial>
        <collision name='collision'>
          <pose>0 0 0 -0.69 -0 -1.5708</pose>
          <geometry>
            <mesh>
              <uri>model://polaris_ranger_ev/meshes/polaris.dae</uri>
              <submesh>
                <name>Steering_Wheel</name>
                <center>1</center>
              </submesh>
            </mesh>
          </geometry>
          <surface>
            <contact>
              <ode>
                <min_depth>0.003</min_depth>
              </ode>
            </contact>
            <bounce/>
            <friction>
              <torsional>
                <ode/>
              </torsional>
              <ode/>
            </friction>
          </surface>
          <max_contacts>10</max_contacts>
        </collision>
        <visual name='visual'>
          <pose>0 0 0 -0.69 -0 -1.5708</pose>
          <geometry>
            <mesh>
              <uri>model://polaris_ranger_ev/meshes/polaris.dae</uri>
              <submesh>
                <name>Steering_Wheel</name>
                <center>1</center>
              </submesh>
            </mesh>
          </geometry>
          <material>
            <script>
              <uri>model://polaris_ranger_ev/materials/scripts</uri>
              <uri>model://polaris_ranger_ev/materials/textures</uri>
              <name>Polaris/Diffuse</name>
            </script>
          </material>
        </visual>
        <self_collide>0</self_collide>
        <enable_wind>0</enable_wind>
        <kinematic>0</kinematic>
        <gravity>1</gravity>
      </link>
      <link name='hand_brake'>
        <pose>0.53 0.07 1.05 0 -0 0</pose>
        <inertial>
          <mass>0.5</mass>
          <inertia>
            <ixx>0.1</ixx>
            <ixy>0</ixy>
            <ixz>0</ixz>
            <iyy>0.1</iyy>
            <iyz>0</iyz>
            <izz>0.05</izz>
          </inertia>
        </inertial>
        <collision name='hand_brake_collision'>
          <pose>0 0 0.05 -0.2 -0 -1.5708</pose>
          <geometry>
            <mesh>
              <uri>model://polaris_ranger_ev/meshes/polaris.dae</uri>
              <submesh>
                <name>E-Brake</name>
                <center>1</center>
              </submesh>
            </mesh>
          </geometry>
          <max_contacts>10</max_contacts>
          <surface>
            <contact>
              <ode/>
            </contact>
            <bounce/>
            <friction>
              <torsional>
                <ode/>
              </torsional>
              <ode/>
            </friction>
          </surface>
        </collision>
        <visual name='hand_brake_visual'>
          <pose>0 0 0.05 -0.2 -0 -1.5708</pose>
          <geometry>
            <mesh>
              <uri>model://polaris_ranger_ev/meshes/polaris.dae</uri>
              <submesh>
                <name>E-Brake</name>
                <center>1</center>
              </submesh>
            </mesh>
          </geometry>
          <material>
            <script>
              <uri>model://polaris_ranger_ev/materials/scripts</uri>
              <uri>model://polaris_ranger_ev/materials/textures</uri>
              <name>Polaris/Diffuse</name>
            </script>
          </material>
        </visual>
        <self_collide>0</self_collide>
        <enable_wind>0</enable_wind>
        <kinematic>0</kinematic>
        <gravity>1</gravity>
      </link>
      <link name='FNR_switch'>
        <pose>0.56 -0.02 1.08 0 0.25 0</pose>
        <inertial>
          <mass>0.1</mass>
          <inertia>
            <ixx>0.1</ixx>
            <ixy>0</ixy>
            <ixz>0</ixz>
            <iyy>6e-05</iyy>
            <iyz>0</iyz>
            <izz>0.1</izz>
          </inertia>
        </inertial>
        <collision name='FNR_switch'>
          <geometry>
            <box>
              <size>0.02 0.04 0.08</size>
            </box>
          </geometry>
          <max_contacts>10</max_contacts>
          <surface>
            <contact>
              <ode/>
            </contact>
            <bounce/>
            <friction>
              <torsional>
                <ode/>
              </torsional>
              <ode/>
            </friction>
          </surface>
        </collision>
        <visual name='FNR_switch_F'>
          <transparency>0</transparency>
          <geometry>
            <box>
              <size>0.02 0.04 0.08</size>
            </box>
          </geometry>
          <material>
            <script>
              <uri>model://polaris_ranger_ev/materials/scripts</uri>
              <uri>model://polaris_ranger_ev/materials/textures</uri>
              <name>FNR_switch_F</name>
            </script>
          </material>
        </visual>
        <visual name='FNR_switch_R'>
          <transparency>1</transparency>
          <geometry>
            <box>
              <size>0.0199 0.0399 0.0799</size>
            </box>
          </geometry>
          <material>
            <script>
              <uri>model://polaris_ranger_ev/materials/scripts</uri>
              <uri>model://polaris_ranger_ev/materials/textures</uri>
              <name>FNR_switch_R</name>
            </script>
          </material>
        </visual>
        <self_collide>0</self_collide>
        <enable_wind>0</enable_wind>
        <kinematic>0</kinematic>
        <gravity>1</gravity>
      </link>
      <joint name='front_left_steering_joint' type='revolute'>
        <child>front_left_wheel_steering_block</child>
        <parent>chassis</parent>
        <axis>
          <xyz>0 0 1</xyz>
          <limit>
            <lower>-0.8727</lower>
            <upper>0.8727</upper>
          </limit>
          <dynamics>
            <damping>50</damping>
            <spring_reference>0</spring_reference>
            <spring_stiffness>0</spring_stiffness>
          </dynamics>
          <use_parent_model_frame>1</use_parent_model_frame>
        </axis>
        <physics>
          <ode>
            <cfm_damping>1</cfm_damping>
            <limit>
              <cfm>0</cfm>
              <erp>0.9</erp>
            </limit>
          </ode>
        </physics>
      </joint>
      <joint name='front_left_wheel_joint' type='revolute'>
        <child>front_left_wheel</child>
        <parent>front_left_wheel_steering_block</parent>
        <axis>
          <xyz>0 1 0.05</xyz>
          <use_parent_model_frame>1</use_parent_model_frame>
          <limit>
            <lower>-1e+16</lower>
            <upper>1e+16</upper>
          </limit>
          <dynamics>
            <spring_reference>0</spring_reference>
            <spring_stiffness>0</spring_stiffness>
          </dynamics>
        </axis>
      </joint>
      <joint name='front_right_steering_joint' type='revolute'>
        <child>front_right_wheel_steering_block</child>
        <parent>chassis</parent>
        <axis>
          <xyz>0 0 1</xyz>
          <limit>
            <lower>-0.8727</lower>
            <upper>0.8727</upper>
          </limit>
          <dynamics>
            <damping>50</damping>
            <spring_reference>0</spring_reference>
            <spring_stiffness>0</spring_stiffness>
          </dynamics>
          <use_parent_model_frame>1</use_parent_model_frame>
        </axis>
        <physics>
          <ode>
            <cfm_damping>1</cfm_damping>
            <limit>
              <cfm>0</cfm>
              <erp>0.9</erp>
            </limit>
          </ode>
        </physics>
      </joint>
      <joint name='front_right_wheel_joint' type='revolute'>
        <child>front_right_wheel</child>
        <parent>front_right_wheel_steering_block</parent>
        <axis>
          <xyz>0 1 -0.05</xyz>
          <use_parent_model_frame>1</use_parent_model_frame>
          <limit>
            <lower>-1e+16</lower>
            <upper>1e+16</upper>
          </limit>
          <dynamics>
            <spring_reference>0</spring_reference>
            <spring_stiffness>0</spring_stiffness>
          </dynamics>
        </axis>
      </joint>
      <joint name='rear_left_wheel_joint' type='revolute'>
        <child>rear_left_wheel</child>
        <parent>chassis</parent>
        <axis>
          <xyz>0 1 0.05</xyz>
          <use_parent_model_frame>1</use_parent_model_frame>
          <limit>
            <lower>-1e+16</lower>
            <upper>1e+16</upper>
          </limit>
          <dynamics>
            <spring_reference>0</spring_reference>
            <spring_stiffness>0</spring_stiffness>
          </dynamics>
        </axis>
      </joint>
      <joint name='rear_right_wheel_joint' type='revolute'>
        <pose>0 0 -0.1 0 -0 0</pose>
        <child>rear_right_wheel</child>
        <parent>chassis</parent>
        <axis>
          <xyz>0 1 -0.05</xyz>
          <use_parent_model_frame>1</use_parent_model_frame>
          <limit>
            <lower>-1e+16</lower>
            <upper>1e+16</upper>
          </limit>
          <dynamics>
            <spring_reference>0</spring_reference>
            <spring_stiffness>0</spring_stiffness>
          </dynamics>
        </axis>
      </joint>
      <joint name='rear_differential_joint' type='revolute'>
        <child>rear_right_wheel</child>
        <parent>rear_left_wheel</parent>
        <axis>
          <xyz>0 1 0</xyz>
          <dynamics>
            <damping>70</damping>
            <spring_reference>0</spring_reference>
            <spring_stiffness>0</spring_stiffness>
          </dynamics>
          <use_parent_model_frame>1</use_parent_model_frame>
          <limit>
            <lower>-1e+16</lower>
            <upper>1e+16</upper>
          </limit>
        </axis>
        <physics>
          <ode>
            <erp>0</erp>
            <cfm>1000</cfm>
            <cfm_damping>1</cfm_damping>
            <limit>
              <cfm>0</cfm>
              <erp>0.2</erp>
            </limit>
          </ode>
        </physics>
      </joint>
      <joint name='gas_joint' type='prismatic'>
        <parent>chassis</parent>
        <child>gas_pedal</child>
        <axis>
          <xyz>1 0 -1</xyz>
          <limit>
            <lower>0</lower>
            <upper>0.08</upper>
          </limit>
          <dynamics>
            <damping>3</damping>
            <spring_reference>0</spring_reference>
            <spring_stiffness>0</spring_stiffness>
          </dynamics>
          <use_parent_model_frame>1</use_parent_model_frame>
        </axis>
        <physics>
          <ode>
            <cfm_damping>1</cfm_damping>
            <limit>
              <cfm>0</cfm>
              <erp>0.2</erp>
            </limit>
          </ode>
        </physics>
      </joint>
      <joint name='brake_joint' type='prismatic'>
        <parent>chassis</parent>
        <child>brake_pedal</child>
        <axis>
          <xyz>1 0 -0.6</xyz>
          <limit>
            <lower>0</lower>
            <upper>0.08</upper>
          </limit>
          <dynamics>
            <damping>3</damping>
            <spring_reference>0</spring_reference>
            <spring_stiffness>0</spring_stiffness>
          </dynamics>
          <use_parent_model_frame>1</use_parent_model_frame>
        </axis>
        <physics>
          <ode>
            <cfm_damping>1</cfm_damping>
            <limit>
              <cfm>0</cfm>
              <erp>0.2</erp>
            </limit>
          </ode>
        </physics>
      </joint>
      <joint name='steering_joint' type='revolute'>
        <pose>-0.002 0 0 0 -0 0</pose>
        <parent>chassis</parent>
        <child>steering_wheel</child>
        <axis>
          <xyz>-1 0 0.84365</xyz>
          <limit>
            <lower>-3.14</lower>
            <upper>3.14</upper>
          </limit>
          <dynamics>
            <damping>1</damping>
            <spring_reference>0</spring_reference>
            <spring_stiffness>0</spring_stiffness>
          </dynamics>
          <use_parent_model_frame>1</use_parent_model_frame>
        </axis>
        <physics>
          <ode>
            <cfm_damping>1</cfm_damping>
            <limit>
              <cfm>0</cfm>
              <erp>0.2</erp>
            </limit>
          </ode>
        </physics>
      </joint>
      <joint name='hand_brake_joint' type='revolute'>
        <parent>chassis</parent>
        <child>hand_brake</child>
        <axis>
          <xyz>0 -1 0</xyz>
          <limit>
            <lower>0</lower>
            <upper>0.6</upper>
          </limit>
          <dynamics>
            <damping>1</damping>
            <spring_reference>0</spring_reference>
            <spring_stiffness>0</spring_stiffness>
          </dynamics>
          <use_parent_model_frame>1</use_parent_model_frame>
        </axis>
        <physics>
          <ode>
            <cfm_damping>1</cfm_damping>
            <limit>
              <cfm>0</cfm>
              <erp>0.2</erp>
            </limit>
          </ode>
        </physics>
      </joint>
      <joint name='FNR_switch_joint' type='revolute'>
        <parent>chassis</parent>
        <child>FNR_switch</child>
        <axis>
          <xyz>0 -1 0</xyz>
          <limit>
            <lower>-0.3</lower>
            <upper>0.3</upper>
          </limit>
          <dynamics>
            <damping>0.01</damping>
            <spring_reference>0</spring_reference>
            <spring_stiffness>0</spring_stiffness>
          </dynamics>
          <use_parent_model_frame>1</use_parent_model_frame>
        </axis>
        <physics>
          <ode>
            <cfm_damping>1</cfm_damping>
            <limit>
              <cfm>0</cfm>
              <erp>0.2</erp>
            </limit>
          </ode>
        </physics>
      </joint>
      <pose>5.50312 -4.56823 0 0 -0 0</pose>
    </model>
    <model name='jersey_barrier'>
      <static>1</static>
      <link name='link'>
        <visual name='visual'>
          <geometry>
            <mesh>
              <uri>model://jersey_barrier/meshes/jersey_barrier.dae</uri>
            </mesh>
          </geometry>
        </visual>
        <collision name='upright'>
          <pose>0 0 0.5715 0 -0 0</pose>
          <geometry>
            <box>
              <size>4.06542 0.3063 1.143</size>
            </box>
          </geometry>
          <max_contacts>10</max_contacts>
          <surface>
            <contact>
              <ode/>
            </contact>
            <bounce/>
            <friction>
              <torsional>
                <ode/>
              </torsional>
              <ode/>
            </friction>
          </surface>
        </collision>
        <collision name='base'>
          <pose>0 0 0.032258 0 -0 0</pose>
          <geometry>
            <box>
              <size>4.06542 0.8107 0.064516</size>
            </box>
          </geometry>
          <max_contacts>10</max_contacts>
          <surface>
            <contact>
              <ode/>
            </contact>
            <bounce/>
            <friction>
              <torsional>
                <ode/>
              </torsional>
              <ode/>
            </friction>
          </surface>
        </collision>
        <collision name='base2'>
          <pose>0 0 0.1 0 -0 0</pose>
          <geometry>
            <box>
              <size>4.06542 0.65 0.1</size>
            </box>
          </geometry>
          <max_contacts>10</max_contacts>
          <surface>
            <contact>
              <ode/>
            </contact>
            <bounce/>
            <friction>
              <torsional>
                <ode/>
              </torsional>
              <ode/>
            </friction>
          </surface>
        </collision>
        <collision name='base3'>
          <pose>0 0 0.2 0 -0 0</pose>
          <geometry>
            <box>
              <size>4.06542 0.5 0.1</size>
            </box>
          </geometry>
          <max_contacts>10</max_contacts>
          <surface>
            <contact>
              <ode/>
            </contact>
            <bounce/>
            <friction>
              <torsional>
                <ode/>
              </torsional>
              <ode/>
            </friction>
          </surface>
        </collision>
        <collision name='left-angle'>
          <pose>0 -0.224 0.2401 0.9 -0 0</pose>
          <geometry>
            <box>
              <size>4.06542 0.5 0.064516</size>
            </box>
          </geometry>
          <max_contacts>10</max_contacts>
          <surface>
            <contact>
              <ode/>
            </contact>
            <bounce/>
            <friction>
              <torsional>
                <ode/>
              </torsional>
              <ode/>
            </friction>
          </surface>
        </collision>
        <collision name='right-angle'>
          <pose>0 0.224 0.2401 -0.9 0 0</pose>
          <geometry>
            <box>
              <size>4.06542 0.5 0.064516</size>
            </box>
          </geometry>
          <max_contacts>10</max_contacts>
          <surface>
            <contact>
              <ode/>
            </contact>
            <bounce/>
            <friction>
              <torsional>
                <ode/>
              </torsional>
              <ode/>
            </friction>
          </surface>
        </collision>
        <self_collide>0</self_collide>
        <enable_wind>0</enable_wind>
        <kinematic>0</kinematic>
        <gravity>1</gravity>
      </link>
      <pose>-6.65745 -9.39618 0 0 -0 0</pose>
    </model>
    <model name='jersey_barrier_0'>
      <static>1</static>
      <link name='link'>
        <visual name='visual'>
          <geometry>
            <mesh>
              <uri>model://jersey_barrier/meshes/jersey_barrier.dae</uri>
            </mesh>
          </geometry>
        </visual>
        <collision name='upright'>
          <pose>0 0 0.5715 0 -0 0</pose>
          <geometry>
            <box>
              <size>4.06542 0.3063 1.143</size>
            </box>
          </geometry>
          <max_contacts>10</max_contacts>
          <surface>
            <contact>
              <ode/>
            </contact>
            <bounce/>
            <friction>
              <torsional>
                <ode/>
              </torsional>
              <ode/>
            </friction>
          </surface>
        </collision>
        <collision name='base'>
          <pose>0 0 0.032258 0 -0 0</pose>
          <geometry>
            <box>
              <size>4.06542 0.8107 0.064516</size>
            </box>
          </geometry>
          <max_contacts>10</max_contacts>
          <surface>
            <contact>
              <ode/>
            </contact>
            <bounce/>
            <friction>
              <torsional>
                <ode/>
              </torsional>
              <ode/>
            </friction>
          </surface>
        </collision>
        <collision name='base2'>
          <pose>0 0 0.1 0 -0 0</pose>
          <geometry>
            <box>
              <size>4.06542 0.65 0.1</size>
            </box>
          </geometry>
          <max_contacts>10</max_contacts>
          <surface>
            <contact>
              <ode/>
            </contact>
            <bounce/>
            <friction>
              <torsional>
                <ode/>
              </torsional>
              <ode/>
            </friction>
          </surface>
        </collision>
        <collision name='base3'>
          <pose>0 0 0.2 0 -0 0</pose>
          <geometry>
            <box>
              <size>4.06542 0.5 0.1</size>
            </box>
          </geometry>
          <max_contacts>10</max_contacts>
          <surface>
            <contact>
              <ode/>
            </contact>
            <bounce/>
            <friction>
              <torsional>
                <ode/>
              </torsional>
              <ode/>
            </friction>
          </surface>
        </collision>
        <collision name='left-angle'>
          <pose>0 -0.224 0.2401 0.9 -0 0</pose>
          <geometry>
            <box>
              <size>4.06542 0.5 0.064516</size>
            </box>
          </geometry>
          <max_contacts>10</max_contacts>
          <surface>
            <contact>
              <ode/>
            </contact>
            <bounce/>
            <friction>
              <torsional>
                <ode/>
              </torsional>
              <ode/>
            </friction>
          </surface>
        </collision>
        <collision name='right-angle'>
          <pose>0 0.224 0.2401 -0.9 0 0</pose>
          <geometry>
            <box>
              <size>4.06542 0.5 0.064516</size>
            </box>
          </geometry>
          <max_contacts>10</max_contacts>
          <surface>
            <contact>
              <ode/>
            </contact>
            <bounce/>
            <friction>
              <torsional>
                <ode/>
              </torsional>
              <ode/>
            </friction>
          </surface>
        </collision>
        <self_collide>0</self_collide>
        <enable_wind>0</enable_wind>
        <kinematic>0</kinematic>
        <gravity>1</gravity>
      </link>
      <pose>-1.8345 -9.38062 0 0 -0 0</pose>
    </model>
    <model name='jersey_barrier_1'>
      <static>1</static>
      <link name='link'>
        <visual name='visual'>
          <geometry>
            <mesh>
              <uri>model://jersey_barrier/meshes/jersey_barrier.dae</uri>
            </mesh>
          </geometry>
        </visual>
        <collision name='upright'>
          <pose>0 0 0.5715 0 -0 0</pose>
          <geometry>
            <box>
              <size>4.06542 0.3063 1.143</size>
            </box>
          </geometry>
          <max_contacts>10</max_contacts>
          <surface>
            <contact>
              <ode/>
            </contact>
            <bounce/>
            <friction>
              <torsional>
                <ode/>
              </torsional>
              <ode/>
            </friction>
          </surface>
        </collision>
        <collision name='base'>
          <pose>0 0 0.032258 0 -0 0</pose>
          <geometry>
            <box>
              <size>4.06542 0.8107 0.064516</size>
            </box>
          </geometry>
          <max_contacts>10</max_contacts>
          <surface>
            <contact>
              <ode/>
            </contact>
            <bounce/>
            <friction>
              <torsional>
                <ode/>
              </torsional>
              <ode/>
            </friction>
          </surface>
        </collision>
        <collision name='base2'>
          <pose>0 0 0.1 0 -0 0</pose>
          <geometry>
            <box>
              <size>4.06542 0.65 0.1</size>
            </box>
          </geometry>
          <max_contacts>10</max_contacts>
          <surface>
            <contact>
              <ode/>
            </contact>
            <bounce/>
            <friction>
              <torsional>
                <ode/>
              </torsional>
              <ode/>
            </friction>
          </surface>
        </collision>
        <collision name='base3'>
          <pose>0 0 0.2 0 -0 0</pose>
          <geometry>
            <box>
              <size>4.06542 0.5 0.1</size>
            </box>
          </geometry>
          <max_contacts>10</max_contacts>
          <surface>
            <contact>
              <ode/>
            </contact>
            <bounce/>
            <friction>
              <torsional>
                <ode/>
              </torsional>
              <ode/>
            </friction>
          </surface>
        </collision>
        <collision name='left-angle'>
          <pose>0 -0.224 0.2401 0.9 -0 0</pose>
          <geometry>
            <box>
              <size>4.06542 0.5 0.064516</size>
            </box>
          </geometry>
          <max_contacts>10</max_contacts>
          <surface>
            <contact>
              <ode/>
            </contact>
            <bounce/>
            <friction>
              <torsional>
                <ode/>
              </torsional>
              <ode/>
            </friction>
          </surface>
        </collision>
        <collision name='right-angle'>
          <pose>0 0.224 0.2401 -0.9 0 0</pose>
          <geometry>
            <box>
              <size>4.06542 0.5 0.064516</size>
            </box>
          </geometry>
          <max_contacts>10</max_contacts>
          <surface>
            <contact>
              <ode/>
            </contact>
            <bounce/>
            <friction>
              <torsional>
                <ode/>
              </torsional>
              <ode/>
            </friction>
          </surface>
        </collision>
        <self_collide>0</self_collide>
        <enable_wind>0</enable_wind>
        <kinematic>0</kinematic>
        <gravity>1</gravity>
      </link>
      <pose>2.81184 -9.40291 0 0 -0 0</pose>
    </model>
    <model name='jersey_barrier_2'>
      <static>1</static>
      <link name='link'>
        <visual name='visual'>
          <geometry>
            <mesh>
              <uri>model://jersey_barrier/meshes/jersey_barrier.dae</uri>
            </mesh>
          </geometry>
        </visual>
        <collision name='upright'>
          <pose>0 0 0.5715 0 -0 0</pose>
          <geometry>
            <box>
              <size>4.06542 0.3063 1.143</size>
            </box>
          </geometry>
          <max_contacts>10</max_contacts>
          <surface>
            <contact>
              <ode/>
            </contact>
            <bounce/>
            <friction>
              <torsional>
                <ode/>
              </torsional>
              <ode/>
            </friction>
          </surface>
        </collision>
        <collision name='base'>
          <pose>0 0 0.032258 0 -0 0</pose>
          <geometry>
            <box>
              <size>4.06542 0.8107 0.064516</size>
            </box>
          </geometry>
          <max_contacts>10</max_contacts>
          <surface>
            <contact>
              <ode/>
            </contact>
            <bounce/>
            <friction>
              <torsional>
                <ode/>
              </torsional>
              <ode/>
            </friction>
          </surface>
        </collision>
        <collision name='base2'>
          <pose>0 0 0.1 0 -0 0</pose>
          <geometry>
            <box>
              <size>4.06542 0.65 0.1</size>
            </box>
          </geometry>
          <max_contacts>10</max_contacts>
          <surface>
            <contact>
              <ode/>
            </contact>
            <bounce/>
            <friction>
              <torsional>
                <ode/>
              </torsional>
              <ode/>
            </friction>
          </surface>
        </collision>
        <collision name='base3'>
          <pose>0 0 0.2 0 -0 0</pose>
          <geometry>
            <box>
              <size>4.06542 0.5 0.1</size>
            </box>
          </geometry>
          <max_contacts>10</max_contacts>
          <surface>
            <contact>
              <ode/>
            </contact>
            <bounce/>
            <friction>
              <torsional>
                <ode/>
              </torsional>
              <ode/>
            </friction>
          </surface>
        </collision>
        <collision name='left-angle'>
          <pose>0 -0.224 0.2401 0.9 -0 0</pose>
          <geometry>
            <box>
              <size>4.06542 0.5 0.064516</size>
            </box>
          </geometry>
          <max_contacts>10</max_contacts>
          <surface>
            <contact>
              <ode/>
            </contact>
            <bounce/>
            <friction>
              <torsional>
                <ode/>
              </torsional>
              <ode/>
            </friction>
          </surface>
        </collision>
        <collision name='right-angle'>
          <pose>0 0.224 0.2401 -0.9 0 0</pose>
          <geometry>
            <box>
              <size>4.06542 0.5 0.064516</size>
            </box>
          </geometry>
          <max_contacts>10</max_contacts>
          <surface>
            <contact>
              <ode/>
            </contact>
            <bounce/>
            <friction>
              <torsional>
                <ode/>
              </torsional>
              <ode/>
            </friction>
          </surface>
        </collision>
        <self_collide>0</self_collide>
        <enable_wind>0</enable_wind>
        <kinematic>0</kinematic>
        <gravity>1</gravity>
      </link>
      <pose>7.4313 -9.37927 0 0 -0 0</pose>
    </model>
    <model name='jersey_barrier_3'>
      <static>1</static>
      <link name='link'>
        <visual name='visual'>
          <geometry>
            <mesh>
              <uri>model://jersey_barrier/meshes/jersey_barrier.dae</uri>
            </mesh>
          </geometry>
        </visual>
        <collision name='upright'>
          <pose>0 0 0.5715 0 -0 0</pose>
          <geometry>
            <box>
              <size>4.06542 0.3063 1.143</size>
            </box>
          </geometry>
          <max_contacts>10</max_contacts>
          <surface>
            <contact>
              <ode/>
            </contact>
            <bounce/>
            <friction>
              <torsional>
                <ode/>
              </torsional>
              <ode/>
            </friction>
          </surface>
        </collision>
        <collision name='base'>
          <pose>0 0 0.032258 0 -0 0</pose>
          <geometry>
            <box>
              <size>4.06542 0.8107 0.064516</size>
            </box>
          </geometry>
          <max_contacts>10</max_contacts>
          <surface>
            <contact>
              <ode/>
            </contact>
            <bounce/>
            <friction>
              <torsional>
                <ode/>
              </torsional>
              <ode/>
            </friction>
          </surface>
        </collision>
        <collision name='base2'>
          <pose>0 0 0.1 0 -0 0</pose>
          <geometry>
            <box>
              <size>4.06542 0.65 0.1</size>
            </box>
          </geometry>
          <max_contacts>10</max_contacts>
          <surface>
            <contact>
              <ode/>
            </contact>
            <bounce/>
            <friction>
              <torsional>
                <ode/>
              </torsional>
              <ode/>
            </friction>
          </surface>
        </collision>
        <collision name='base3'>
          <pose>0 0 0.2 0 -0 0</pose>
          <geometry>
            <box>
              <size>4.06542 0.5 0.1</size>
            </box>
          </geometry>
          <max_contacts>10</max_contacts>
          <surface>
            <contact>
              <ode/>
            </contact>
            <bounce/>
            <friction>
              <torsional>
                <ode/>
              </torsional>
              <ode/>
            </friction>
          </surface>
        </collision>
        <collision name='left-angle'>
          <pose>0 -0.224 0.2401 0.9 -0 0</pose>
          <geometry>
            <box>
              <size>4.06542 0.5 0.064516</size>
            </box>
          </geometry>
          <max_contacts>10</max_contacts>
          <surface>
            <contact>
              <ode/>
            </contact>
            <bounce/>
            <friction>
              <torsional>
                <ode/>
              </torsional>
              <ode/>
            </friction>
          </surface>
        </collision>
        <collision name='right-angle'>
          <pose>0 0.224 0.2401 -0.9 0 0</pose>
          <geometry>
            <box>
              <size>4.06542 0.5 0.064516</size>
            </box>
          </geometry>
          <max_contacts>10</max_contacts>
          <surface>
            <contact>
              <ode/>
            </contact>
            <bounce/>
            <friction>
              <torsional>
                <ode/>
              </torsional>
              <ode/>
            </friction>
          </surface>
        </collision>
        <self_collide>0</self_collide>
        <enable_wind>0</enable_wind>
        <kinematic>0</kinematic>
        <gravity>1</gravity>
      </link>
      <pose>-7.11244 9.11903 0 0 -0 0</pose>
    </model>
    <model name='jersey_barrier_4'>
      <static>1</static>
      <link name='link'>
        <visual name='visual'>
          <geometry>
            <mesh>
              <uri>model://jersey_barrier/meshes/jersey_barrier.dae</uri>
            </mesh>
          </geometry>
        </visual>
        <collision name='upright'>
          <pose>0 0 0.5715 0 -0 0</pose>
          <geometry>
            <box>
              <size>4.06542 0.3063 1.143</size>
            </box>
          </geometry>
          <max_contacts>10</max_contacts>
          <surface>
            <contact>
              <ode/>
            </contact>
            <bounce/>
            <friction>
              <torsional>
                <ode/>
              </torsional>
              <ode/>
            </friction>
          </surface>
        </collision>
        <collision name='base'>
          <pose>0 0 0.032258 0 -0 0</pose>
          <geometry>
            <box>
              <size>4.06542 0.8107 0.064516</size>
            </box>
          </geometry>
          <max_contacts>10</max_contacts>
          <surface>
            <contact>
              <ode/>
            </contact>
            <bounce/>
            <friction>
              <torsional>
                <ode/>
              </torsional>
              <ode/>
            </friction>
          </surface>
        </collision>
        <collision name='base2'>
          <pose>0 0 0.1 0 -0 0</pose>
          <geometry>
            <box>
              <size>4.06542 0.65 0.1</size>
            </box>
          </geometry>
          <max_contacts>10</max_contacts>
          <surface>
            <contact>
              <ode/>
            </contact>
            <bounce/>
            <friction>
              <torsional>
                <ode/>
              </torsional>
              <ode/>
            </friction>
          </surface>
        </collision>
        <collision name='base3'>
          <pose>0 0 0.2 0 -0 0</pose>
          <geometry>
            <box>
              <size>4.06542 0.5 0.1</size>
            </box>
          </geometry>
          <max_contacts>10</max_contacts>
          <surface>
            <contact>
              <ode/>
            </contact>
            <bounce/>
            <friction>
              <torsional>
                <ode/>
              </torsional>
              <ode/>
            </friction>
          </surface>
        </collision>
        <collision name='left-angle'>
          <pose>0 -0.224 0.2401 0.9 -0 0</pose>
          <geometry>
            <box>
              <size>4.06542 0.5 0.064516</size>
            </box>
          </geometry>
          <max_contacts>10</max_contacts>
          <surface>
            <contact>
              <ode/>
            </contact>
            <bounce/>
            <friction>
              <torsional>
                <ode/>
              </torsional>
              <ode/>
            </friction>
          </surface>
        </collision>
        <collision name='right-angle'>
          <pose>0 0.224 0.2401 -0.9 0 0</pose>
          <geometry>
            <box>
              <size>4.06542 0.5 0.064516</size>
            </box>
          </geometry>
          <max_contacts>10</max_contacts>
          <surface>
            <contact>
              <ode/>
            </contact>
            <bounce/>
            <friction>
              <torsional>
                <ode/>
              </torsional>
              <ode/>
            </friction>
          </surface>
        </collision>
        <self_collide>0</self_collide>
        <enable_wind>0</enable_wind>
        <kinematic>0</kinematic>
        <gravity>1</gravity>
      </link>
      <pose>-2.47812 9.32762 0 0 -0 0</pose>
    </model>
    <model name='jersey_barrier_5'>
      <static>1</static>
      <link name='link'>
        <visual name='visual'>
          <geometry>
            <mesh>
              <uri>model://jersey_barrier/meshes/jersey_barrier.dae</uri>
            </mesh>
          </geometry>
        </visual>
        <collision name='upright'>
          <pose>0 0 0.5715 0 -0 0</pose>
          <geometry>
            <box>
              <size>4.06542 0.3063 1.143</size>
            </box>
          </geometry>
          <max_contacts>10</max_contacts>
          <surface>
            <contact>
              <ode/>
            </contact>
            <bounce/>
            <friction>
              <torsional>
                <ode/>
              </torsional>
              <ode/>
            </friction>
          </surface>
        </collision>
        <collision name='base'>
          <pose>0 0 0.032258 0 -0 0</pose>
          <geometry>
            <box>
              <size>4.06542 0.8107 0.064516</size>
            </box>
          </geometry>
          <max_contacts>10</max_contacts>
          <surface>
            <contact>
              <ode/>
            </contact>
            <bounce/>
            <friction>
              <torsional>
                <ode/>
              </torsional>
              <ode/>
            </friction>
          </surface>
        </collision>
        <collision name='base2'>
          <pose>0 0 0.1 0 -0 0</pose>
          <geometry>
            <box>
              <size>4.06542 0.65 0.1</size>
            </box>
          </geometry>
          <max_contacts>10</max_contacts>
          <surface>
            <contact>
              <ode/>
            </contact>
            <bounce/>
            <friction>
              <torsional>
                <ode/>
              </torsional>
              <ode/>
            </friction>
          </surface>
        </collision>
        <collision name='base3'>
          <pose>0 0 0.2 0 -0 0</pose>
          <geometry>
            <box>
              <size>4.06542 0.5 0.1</size>
            </box>
          </geometry>
          <max_contacts>10</max_contacts>
          <surface>
            <contact>
              <ode/>
            </contact>
            <bounce/>
            <friction>
              <torsional>
                <ode/>
              </torsional>
              <ode/>
            </friction>
          </surface>
        </collision>
        <collision name='left-angle'>
          <pose>0 -0.224 0.2401 0.9 -0 0</pose>
          <geometry>
            <box>
              <size>4.06542 0.5 0.064516</size>
            </box>
          </geometry>
          <max_contacts>10</max_contacts>
          <surface>
            <contact>
              <ode/>
            </contact>
            <bounce/>
            <friction>
              <torsional>
                <ode/>
              </torsional>
              <ode/>
            </friction>
          </surface>
        </collision>
        <collision name='right-angle'>
          <pose>0 0.224 0.2401 -0.9 0 0</pose>
          <geometry>
            <box>
              <size>4.06542 0.5 0.064516</size>
            </box>
          </geometry>
          <max_contacts>10</max_contacts>
          <surface>
            <contact>
              <ode/>
            </contact>
            <bounce/>
            <friction>
              <torsional>
                <ode/>
              </torsional>
              <ode/>
            </friction>
          </surface>
        </collision>
        <self_collide>0</self_collide>
        <enable_wind>0</enable_wind>
        <kinematic>0</kinematic>
        <gravity>1</gravity>
      </link>
      <pose>2.29939 9.37988 0 0 -0 0</pose>
    </model>
    <model name='jersey_barrier_6'>
      <static>1</static>
      <link name='link'>
        <visual name='visual'>
          <geometry>
            <mesh>
              <uri>model://jersey_barrier/meshes/jersey_barrier.dae</uri>
            </mesh>
          </geometry>
        </visual>
        <collision name='upright'>
          <pose>0 0 0.5715 0 -0 0</pose>
          <geometry>
            <box>
              <size>4.06542 0.3063 1.143</size>
            </box>
          </geometry>
          <max_contacts>10</max_contacts>
          <surface>
            <contact>
              <ode/>
            </contact>
            <bounce/>
            <friction>
              <torsional>
                <ode/>
              </torsional>
              <ode/>
            </friction>
          </surface>
        </collision>
        <collision name='base'>
          <pose>0 0 0.032258 0 -0 0</pose>
          <geometry>
            <box>
              <size>4.06542 0.8107 0.064516</size>
            </box>
          </geometry>
          <max_contacts>10</max_contacts>
          <surface>
            <contact>
              <ode/>
            </contact>
            <bounce/>
            <friction>
              <torsional>
                <ode/>
              </torsional>
              <ode/>
            </friction>
          </surface>
        </collision>
        <collision name='base2'>
          <pose>0 0 0.1 0 -0 0</pose>
          <geometry>
            <box>
              <size>4.06542 0.65 0.1</size>
            </box>
          </geometry>
          <max_contacts>10</max_contacts>
          <surface>
            <contact>
              <ode/>
            </contact>
            <bounce/>
            <friction>
              <torsional>
                <ode/>
              </torsional>
              <ode/>
            </friction>
          </surface>
        </collision>
        <collision name='base3'>
          <pose>0 0 0.2 0 -0 0</pose>
          <geometry>
            <box>
              <size>4.06542 0.5 0.1</size>
            </box>
          </geometry>
          <max_contacts>10</max_contacts>
          <surface>
            <contact>
              <ode/>
            </contact>
            <bounce/>
            <friction>
              <torsional>
                <ode/>
              </torsional>
              <ode/>
            </friction>
          </surface>
        </collision>
        <collision name='left-angle'>
          <pose>0 -0.224 0.2401 0.9 -0 0</pose>
          <geometry>
            <box>
              <size>4.06542 0.5 0.064516</size>
            </box>
          </geometry>
          <max_contacts>10</max_contacts>
          <surface>
            <contact>
              <ode/>
            </contact>
            <bounce/>
            <friction>
              <torsional>
                <ode/>
              </torsional>
              <ode/>
            </friction>
          </surface>
        </collision>
        <collision name='right-angle'>
          <pose>0 0.224 0.2401 -0.9 0 0</pose>
          <geometry>
            <box>
              <size>4.06542 0.5 0.064516</size>
            </box>
          </geometry>
          <max_contacts>10</max_contacts>
          <surface>
            <contact>
              <ode/>
            </contact>
            <bounce/>
            <friction>
              <torsional>
                <ode/>
              </torsional>
              <ode/>
            </friction>
          </surface>
        </collision>
        <self_collide>0</self_collide>
        <enable_wind>0</enable_wind>
        <kinematic>0</kinematic>
        <gravity>1</gravity>
      </link>
      <pose>6.90559 9.44069 0 0 -0 0</pose>
    </model>
    <model name='Construction Barrel_0'>
      <link name='link'>
        <inertial>
          <pose>0 0 0.4 0 -0 0</pose>
          <mass>500</mass>
          <inertia>
            <ixx>51.2096</ixx>
            <iyy>51.2096</iyy>
            <izz>25</izz>
            <ixy>0</ixy>
            <ixz>0</ixz>
            <iyz>0</iyz>
          </inertia>
        </inertial>
        <collision name='collision'>
          <geometry>
            <mesh>
              <uri>model://construction_barrel/meshes/construction_barrel.dae</uri>
            </mesh>
          </geometry>
          <max_contacts>10</max_contacts>
          <surface>
            <contact>
              <ode/>
            </contact>
            <bounce/>
            <friction>
              <torsional>
                <ode/>
              </torsional>
              <ode/>
            </friction>
          </surface>
        </collision>
        <visual name='visual'>
          <geometry>
            <mesh>
              <uri>model://construction_barrel/meshes/construction_barrel.dae</uri>
            </mesh>
          </geometry>
        </visual>
        <self_collide>0</self_collide>
        <enable_wind>0</enable_wind>
        <kinematic>0</kinematic>
        <gravity>1</gravity>
      </link>
      <pose>9.26597 -7.70178 0 0 -0 0</pose>
    </model>
    <model name='Construction Barrel_1'>
      <link name='link'>
        <inertial>
          <pose>0 0 0.4 0 -0 0</pose>
          <mass>500</mass>
          <inertia>
            <ixx>51.2096</ixx>
            <iyy>51.2096</iyy>
            <izz>25</izz>
            <ixy>0</ixy>
            <ixz>0</ixz>
            <iyz>0</iyz>
          </inertia>
        </inertial>
        <collision name='collision'>
          <geometry>
            <mesh>
              <uri>model://construction_barrel/meshes/construction_barrel.dae</uri>
            </mesh>
          </geometry>
          <max_contacts>10</max_contacts>
          <surface>
            <contact>
              <ode/>
            </contact>
            <bounce/>
            <friction>
              <torsional>
                <ode/>
              </torsional>
              <ode/>
            </friction>
          </surface>
        </collision>
        <visual name='visual'>
          <geometry>
            <mesh>
              <uri>model://construction_barrel/meshes/construction_barrel.dae</uri>
            </mesh>
          </geometry>
        </visual>
        <self_collide>0</self_collide>
        <enable_wind>0</enable_wind>
        <kinematic>0</kinematic>
        <gravity>1</gravity>
      </link>
      <pose>9.49004 7.33741 0 0 -0 0</pose>
    </model>
    <model name='Construction Barrel_2'>
      <link name='link'>
        <inertial>
          <pose>0 0 0.4 0 -0 0</pose>
          <mass>500</mass>
          <inertia>
            <ixx>51.2096</ixx>
            <iyy>51.2096</iyy>
            <izz>25</izz>
            <ixy>0</ixy>
            <ixz>0</ixz>
            <iyz>0</iyz>
          </inertia>
        </inertial>
        <collision name='collision'>
          <geometry>
            <mesh>
              <uri>model://construction_barrel/meshes/construction_barrel.dae</uri>
            </mesh>
          </geometry>
          <max_contacts>10</max_contacts>
          <surface>
            <contact>
              <ode/>
            </contact>
            <bounce/>
            <friction>
              <torsional>
                <ode/>
              </torsional>
              <ode/>
            </friction>
          </surface>
        </collision>
        <visual name='visual'>
          <geometry>
            <mesh>
              <uri>model://construction_barrel/meshes/construction_barrel.dae</uri>
            </mesh>
          </geometry>
        </visual>
        <self_collide>0</self_collide>
        <enable_wind>0</enable_wind>
        <kinematic>0</kinematic>
        <gravity>1</gravity>
      </link>
      <pose>9.35723 3.98842 0 0 -0 0</pose>
    </model>
    <model name='Construction Barrel_3'>
      <link name='link'>
        <inertial>
          <pose>0 0 0.4 0 -0 0</pose>
          <mass>500</mass>
          <inertia>
            <ixx>51.2096</ixx>
            <iyy>51.2096</iyy>
            <izz>25</izz>
            <ixy>0</ixy>
            <ixz>0</ixz>
            <iyz>0</iyz>
          </inertia>
        </inertial>
        <collision name='collision'>
          <geometry>
            <mesh>
              <uri>model://construction_barrel/meshes/construction_barrel.dae</uri>
            </mesh>
          </geometry>
          <max_contacts>10</max_contacts>
          <surface>
            <contact>
              <ode/>
            </contact>
            <bounce/>
            <friction>
              <torsional>
                <ode/>
              </torsional>
              <ode/>
            </friction>
          </surface>
        </collision>
        <visual name='visual'>
          <geometry>
            <mesh>
              <uri>model://construction_barrel/meshes/construction_barrel.dae</uri>
            </mesh>
          </geometry>
        </visual>
        <self_collide>0</self_collide>
        <enable_wind>0</enable_wind>
        <kinematic>0</kinematic>
        <gravity>1</gravity>
      </link>
      <pose>9.40935 -5.2274 0 0 -0 0</pose>
    </model>
    <model name='Construction Barrel_4'>
      <link name='link'>
        <inertial>
          <pose>0 0 0.4 0 -0 0</pose>
          <mass>500</mass>
          <inertia>
            <ixx>51.2096</ixx>
            <iyy>51.2096</iyy>
            <izz>25</izz>
            <ixy>0</ixy>
            <ixz>0</ixz>
            <iyz>0</iyz>
          </inertia>
        </inertial>
        <collision name='collision'>
          <geometry>
            <mesh>
              <uri>model://construction_barrel/meshes/construction_barrel.dae</uri>
            </mesh>
          </geometry>
          <max_contacts>10</max_contacts>
          <surface>
            <contact>
              <ode/>
            </contact>
            <bounce/>
            <friction>
              <torsional>
                <ode/>
              </torsional>
              <ode/>
            </friction>
          </surface>
        </collision>
        <visual name='visual'>
          <geometry>
            <mesh>
              <uri>model://construction_barrel/meshes/construction_barrel.dae</uri>
            </mesh>
          </geometry>
        </visual>
        <self_collide>0</self_collide>
        <enable_wind>0</enable_wind>
        <kinematic>0</kinematic>
        <gravity>1</gravity>
      </link>
      <pose>9.40758 -2.22855 0 0 -0 0</pose>
    </model>
    <model name='Construction Barrel_5'>
      <link name='link'>
        <inertial>
          <pose>0 0 0.4 0 -0 0</pose>
          <mass>500</mass>
          <inertia>
            <ixx>51.2096</ixx>
            <iyy>51.2096</iyy>
            <izz>25</izz>
            <ixy>0</ixy>
            <ixz>0</ixz>
            <iyz>0</iyz>
          </inertia>
        </inertial>
        <collision name='collision'>
          <geometry>
            <mesh>
              <uri>model://construction_barrel/meshes/construction_barrel.dae</uri>
            </mesh>
          </geometry>
          <max_contacts>10</max_contacts>
          <surface>
            <contact>
              <ode/>
            </contact>
            <bounce/>
            <friction>
              <torsional>
                <ode/>
              </torsional>
              <ode/>
            </friction>
          </surface>
        </collision>
        <visual name='visual'>
          <geometry>
            <mesh>
              <uri>model://construction_barrel/meshes/construction_barrel.dae</uri>
            </mesh>
          </geometry>
        </visual>
        <self_collide>0</self_collide>
        <enable_wind>0</enable_wind>
        <kinematic>0</kinematic>
        <gravity>1</gravity>
      </link>
      <pose>9.39293 0.919648 0 0 -0 0</pose>
    </model>
    <model name='Construction Cone_0'>
      <link name='link'>
        <collision name='collision'>
          <geometry>
            <mesh>
              <scale>10 10 10</scale>
              <uri>model://construction_cone/meshes/construction_cone.dae</uri>
            </mesh>
          </geometry>
          <max_contacts>10</max_contacts>
          <surface>
            <contact>
              <ode/>
            </contact>
            <bounce/>
            <friction>
              <torsional>
                <ode/>
              </torsional>
              <ode/>
            </friction>
          </surface>
        </collision>
        <visual name='visual'>
          <geometry>
            <mesh>
              <scale>10 10 10</scale>
              <uri>model://construction_cone/meshes/construction_cone.dae</uri>
            </mesh>
          </geometry>
        </visual>
        <self_collide>0</self_collide>
        <inertial>
          <inertia>
            <ixx>1</ixx>
            <ixy>0</ixy>
            <ixz>0</ixz>
            <iyy>1</iyy>
            <iyz>0</iyz>
            <izz>1</izz>
          </inertia>
          <mass>1</mass>
        </inertial>
        <enable_wind>0</enable_wind>
        <kinematic>0</kinematic>
        <gravity>1</gravity>
      </link>
      <pose>2.94259 -0.067967 0 0 -0 0</pose>
    </model>
    <model name='Construction Cone_1'>
      <link name='link'>
        <collision name='collision'>
          <geometry>
            <mesh>
              <scale>10 10 10</scale>
              <uri>model://construction_cone/meshes/construction_cone.dae</uri>
            </mesh>
          </geometry>
          <max_contacts>10</max_contacts>
          <surface>
            <contact>
              <ode/>
            </contact>
            <bounce/>
            <friction>
              <torsional>
                <ode/>
              </torsional>
              <ode/>
            </friction>
          </surface>
        </collision>
        <visual name='visual'>
          <geometry>
            <mesh>
              <scale>10 10 10</scale>
              <uri>model://construction_cone/meshes/construction_cone.dae</uri>
            </mesh>
          </geometry>
        </visual>
        <self_collide>0</self_collide>
        <inertial>
          <inertia>
            <ixx>1</ixx>
            <ixy>0</ixy>
            <ixz>0</ixz>
            <iyy>1</iyy>
            <iyz>0</iyz>
            <izz>1</izz>
          </inertia>
          <mass>1</mass>
        </inertial>
        <enable_wind>0</enable_wind>
        <kinematic>0</kinematic>
        <gravity>1</gravity>
      </link>
      <pose>3.33192 3.24076 0 0 -0 0</pose>
    </model>
    <model name='Construction Cone_2'>
      <link name='link'>
        <collision name='collision'>
          <geometry>
            <mesh>
              <scale>10 10 10</scale>
              <uri>model://construction_cone/meshes/construction_cone.dae</uri>
            </mesh>
          </geometry>
          <max_contacts>10</max_contacts>
          <surface>
            <contact>
              <ode/>
            </contact>
            <bounce/>
            <friction>
              <torsional>
                <ode/>
              </torsional>
              <ode/>
            </friction>
          </surface>
        </collision>
        <visual name='visual'>
          <geometry>
            <mesh>
              <scale>10 10 10</scale>
              <uri>model://construction_cone/meshes/construction_cone.dae</uri>
            </mesh>
          </geometry>
        </visual>
        <self_collide>0</self_collide>
        <inertial>
          <inertia>
            <ixx>1</ixx>
            <ixy>0</ixy>
            <ixz>0</ixz>
            <iyy>1</iyy>
            <iyz>0</iyz>
            <izz>1</izz>
          </inertia>
          <mass>1</mass>
        </inertial>
        <enable_wind>0</enable_wind>
        <kinematic>0</kinematic>
        <gravity>1</gravity>
      </link>
      <pose>-0.37 3.2363 0 0 -0 0</pose>
    </model>
    <model name='Construction Cone_3'>
      <link name='link'>
        <collision name='collision'>
          <geometry>
            <mesh>
              <scale>10 10 10</scale>
              <uri>model://construction_cone/meshes/construction_cone.dae</uri>
            </mesh>
          </geometry>
          <max_contacts>10</max_contacts>
          <surface>
            <contact>
              <ode/>
            </contact>
            <bounce/>
            <friction>
              <torsional>
                <ode/>
              </torsional>
              <ode/>
            </friction>
          </surface>
        </collision>
        <visual name='visual'>
          <geometry>
            <mesh>
              <scale>10 10 10</scale>
              <uri>model://construction_cone/meshes/construction_cone.dae</uri>
            </mesh>
          </geometry>
        </visual>
        <self_collide>0</self_collide>
        <inertial>
          <inertia>
            <ixx>1</ixx>
            <ixy>0</ixy>
            <ixz>0</ixz>
            <iyy>1</iyy>
            <iyz>0</iyz>
            <izz>1</izz>
          </inertia>
          <mass>1</mass>
        </inertial>
        <enable_wind>0</enable_wind>
        <kinematic>0</kinematic>
        <gravity>1</gravity>
      </link>
      <pose>0.624481 0.551521 0 0 -0 0</pose>
    </model>
    <model name='Lamp Post'>
      <static>1</static>
      <link name='link'>
        <collision name='collision'>
          <geometry>
            <mesh>
              <uri>model://lamp_post/meshes/lamp_post.dae</uri>
              <scale>3 3 3</scale>
            </mesh>
          </geometry>
          <max_contacts>10</max_contacts>
          <surface>
            <contact>
              <ode/>
            </contact>
            <bounce/>
            <friction>
              <torsional>
                <ode/>
              </torsional>
              <ode/>
            </friction>
          </surface>
        </collision>
        <visual name='visual'>
          <geometry>
            <mesh>
              <uri>model://lamp_post/meshes/lamp_post.dae</uri>
              <scale>3 3 3</scale>
            </mesh>
          </geometry>
        </visual>
        <self_collide>0</self_collide>
        <enable_wind>0</enable_wind>
        <kinematic>0</kinematic>
        <gravity>1</gravity>
      </link>
      <pose>9.60908 8.80967 0 0 -0 0</pose>
    </model>
    <model name='Lamp Post_0'>
      <static>1</static>
      <link name='link'>
        <collision name='collision'>
          <geometry>
            <mesh>
              <uri>model://lamp_post/meshes/lamp_post.dae</uri>
              <scale>3 3 3</scale>
            </mesh>
          </geometry>
          <max_contacts>10</max_contacts>
          <surface>
            <contact>
              <ode/>
            </contact>
            <bounce/>
            <friction>
              <torsional>
                <ode/>
              </torsional>
              <ode/>
            </friction>
          </surface>
        </collision>
        <visual name='visual'>
          <geometry>
            <mesh>
              <uri>model://lamp_post/meshes/lamp_post.dae</uri>
              <scale>3 3 3</scale>
            </mesh>
          </geometry>
        </visual>
        <self_collide>0</self_collide>
        <enable_wind>0</enable_wind>
        <kinematic>0</kinematic>
        <gravity>1</gravity>
      </link>
      <pose>-9.35588 8.4159 0 0 -0 0</pose>
    </model>
    <model name='Lamp Post_1'>
      <static>1</static>
      <link name='link'>
        <collision name='collision'>
          <geometry>
            <mesh>
              <uri>model://lamp_post/meshes/lamp_post.dae</uri>
              <scale>3 3 3</scale>
            </mesh>
          </geometry>
          <max_contacts>10</max_contacts>
          <surface>
            <contact>
              <ode/>
            </contact>
            <bounce/>
            <friction>
              <torsional>
                <ode/>
              </torsional>
              <ode/>
            </friction>
          </surface>
        </collision>
        <visual name='visual'>
          <geometry>
            <mesh>
              <uri>model://lamp_post/meshes/lamp_post.dae</uri>
              <scale>3 3 3</scale>
            </mesh>
          </geometry>
        </visual>
        <self_collide>0</self_collide>
        <enable_wind>0</enable_wind>
        <kinematic>0</kinematic>
        <gravity>1</gravity>
      </link>
      <pose>-9.24439 -8.71353 0 0 -0 0</pose>
    </model>
    <model name='Lamp Post_2'>
      <static>1</static>
      <link name='link'>
        <collision name='collision'>
          <geometry>
            <mesh>
              <uri>model://lamp_post/meshes/lamp_post.dae</uri>
              <scale>3 3 3</scale>
            </mesh>
          </geometry>
          <max_contacts>10</max_contacts>
          <surface>
            <contact>
              <ode/>
            </contact>
            <bounce/>
            <friction>
              <torsional>
                <ode/>
              </torsional>
              <ode/>
            </friction>
          </surface>
        </collision>
        <visual name='visual'>
          <geometry>
            <mesh>
              <uri>model://lamp_post/meshes/lamp_post.dae</uri>
              <scale>3 3 3</scale>
            </mesh>
          </geometry>
        </visual>
        <self_collide>0</self_collide>
        <enable_wind>0</enable_wind>
        <kinematic>0</kinematic>
        <gravity>1</gravity>
      </link>
      <pose>9.3027 -8.68834 0 0 -0 0</pose>
    </model>
    <model name='Big_box'>
      <link name='link'>
        <pose>0.526234 -0.111526 -0.388989 -1.5539 0 0</pose>
        <inertial>
          <mass>40</mass>
          <inertia>
            <ixx>1</ixx>
            <ixy>0</ixy>
            <ixz>0</ixz>
            <iyy>1</iyy>
            <iyz>0</iyz>
            <izz>1</izz>
          </inertia>
          <pose>0 0 0 0 -0 0</pose>
        </inertial>
        <self_collide>0</self_collide>
        <kinematic>0</kinematic>
        <gravity>1</gravity>
        <visual name='visual'>
          <geometry>
            <mesh>
              <uri>model://big_box/meshes/big_box.dae</uri>
              <scale>1.25 0.2 1</scale>
            </mesh>
          </geometry>
          <pose>0 0 0 0 -0 0</pose>
          <cast_shadows>1</cast_shadows>
          <transparency>0</transparency>
          <material>
            <shader type='vertex'>
              <normal_map>__default__</normal_map>
            </shader>
          </material>
        </visual>
        <collision name='collision'>
          <laser_retro>0</laser_retro>
          <max_contacts>10</max_contacts>
          <pose>0 0 0 0 -0 0</pose>
          <geometry>
            <box>
              <size>1.5 0.2 1.5</size>
            </box>
          </geometry>
          <surface>
            <friction>
              <ode>
                <mu>1</mu>
                <mu2>1</mu2>
                <fdir1>0 0 0</fdir1>
                <slip1>0</slip1>
                <slip2>0</slip2>
              </ode>
              <torsional>
                <coefficient>1</coefficient>
                <patch_radius>0</patch_radius>
                <surface_radius>0</surface_radius>
                <use_patch_radius>1</use_patch_radius>
                <ode>
                  <slip>0</slip>
                </ode>
              </torsional>
            </friction>
            <bounce>
              <restitution_coefficient>0</restitution_coefficient>
              <threshold>1e+06</threshold>
            </bounce>
            <contact>
              <collide_without_contact>0</collide_without_contact>
              <collide_without_contact_bitmask>1</collide_without_contact_bitmask>
              <collide_bitmask>1</collide_bitmask>
              <ode>
                <soft_cfm>0</soft_cfm>
                <soft_erp>0.2</soft_erp>
                <kp>1e+13</kp>
                <kd>1</kd>
                <max_vel>0.1</max_vel>
                <min_depth>0.001</min_depth>
              </ode>
              <bullet>
                <split_impulse>1</split_impulse>
                <split_impulse_penetration_threshold>-0.01</split_impulse_penetration_threshold>
                <soft_cfm>0</soft_cfm>
                <soft_erp>0.2</soft_erp>
                <kp>1e+13</kp>
                <kd>1</kd>
              </bullet>
            </contact>
          </surface>
        </collision>
        <enable_wind>0</enable_wind>
      </link>
      <static>0</static>
      <allow_auto_disable>1</allow_auto_disable>
      <pose>1.43022 2.5418 0 0 -0 0</pose>
    </model>
  </world>
</sdf>
